Workbook

Sheet Old P110
A1: EOS P110 — Old P110 Build Log
A2: Build info | D2: Slot 1 bucket | F2: Slot 2 bucket | H2: Usage | I2: Result | K2: Powder source (FIFO: funnel→slot1→slot2) | N2: Slot remaining | P2: Notes | Q2: Calculated detail (click + to expand)
A4: Build # | B4: Date | C4: Cleaned Chamber? | D4: Slot 1 Cycle | E4: Slot 1 Bucket | F4: Slot 2 Cycle | G4: Slot 2 Bucket | H4: Calc. usage (kg) | I4: Total drawn (kg) | J4: Total LEFT (kg) | K4: Draw from funnel | L4: Draw from slot 1 | M4: Draw from slot 2 | N4: Slot 1 left | O4: Slot 2 left | P4: Notes | Q4: Eff S1 Cyc | R4: Eff S1 Bkt | S4: Eff S2 Cyc | T4: Eff S2 Bkt | U4: Slot 1 Key | V4: Slot 2 Key | W4: Swap1? | X4: Swap2? | Y4: Funnel1 bkt | Z4: Funnel1 start | AA4: Funnel1 used | AB4: Funnel1 end | AC4: Funnel2 bkt | AD4: Funnel2 start | AE4: Funnel2 used | AF4: Funnel2 end | AG4: Roller fill (kg) | AH4: Slot 1 avail | AI4: Slot 2 avail | AJ4: Total avail
A5: temp search | D5: M1 | E5: A | F5: M1 | G5: B | H5: 1.85 | I5: =IFERROR(IF(H5="","",H5+AG5),"") -> 1.85 | J5: =IFERROR(IF(OR(I5="",AJ5=""),"",AJ5-(AK5+AL5)),"") -> 7.39 | K5: =IF(AND(AA5>0,AE5>0),TEXT(AA5,"0.000")&" kg "&Y5&" (funnel)"&" + "&TEXT(AE5,"0.000")&" kg "&AC5&" (funnel)",IF(AA5>0,TEXT(AA5,"0.000")&" kg "&Y5&" (funnel)",IF(AE5>0,TEXT(AE5,"0.000")&" kg "&AC5&" (funnel)",""))) | L5: =IF(OR(AK5="",AK5=0,U5=""),"",TEXT(AK5,"0.000")&" kg "&U5) -> 1.850 kg M1A- | M5: =IF(OR(AL5="",AL5=0,V5=""),"",TEXT(AL5,"0.000")&" kg "&V5) | N5: =IF(OR(I5="",U5=""),"",TEXT(MAX(0,(AH5-AK5-IF(Y5=U5,AA5,0)-IF(AC5=U5,AE5,0))),"0.000")&" kg "&U5) -> 2.670 kg M1A- | O5: =IF(OR(I5="",V5=""),"",TEXT(MAX(0,(AI5-AL5-IF(Y5=V5,AA5,0)-IF(AC5=V5,AE5,0))),"0.000")&" kg "&V5) -> 4.720 kg M1B- | Q5: =IF($A5="","",IF(D5="","",D5)) -> M1 | R5: =IF($A5="","",IF(E5="","",E5)) -> A | S5: =IF($A5="","",IF(F5="","",F5)) -> M1 | T5: =IF($A5="","",IF(G5="","",G5)) -> B | U5: =IF(OR(Q5="",R5=""),"",Q5&R5&"-") -> M1A- | V5: =IF(OR(S5="",T5=""),"",S5&T5&"-") -> M1B- | W5: =0 -> 0 | X5: =0 -> 0 | Y5: ="" | Z5: =0 -> 0 | AA5: =IFERROR(IF(I5="",0,MAX(0,MIN(Z5,I5))),0) -> 0 | AB5: =IFERROR(Z5-AA5,0) -> 0 | AC5: ="" | AD5: =0 -> 0 | AE5: =IFERROR(IF(I5="",0,MAX(0,MIN(AD5,I5-AA5))),0) -> 0 | AF5: =IFERROR(AD5-AE5,0) -> 0 | AG5: =IFERROR(IF(C5="Y",Settings!$B$4+Settings!$B$5,0),0) -> 0 | AH5: =IFERROR(IF(U5="","",IFERROR(VLOOKUP(U5,'Bucket Status'!$A$4:$B$75,2,FALSE()),0)-0),"") -> 4.52 | AI5: =IFERROR(IF(V5="","",IFERROR(VLOOKUP(V5,'Bucket Status'!$A$4:$B$75,2,FALSE()),0)-0),"") -> 4.72 | AJ5: =IFERROR(IF(AH5="","",AH5+IF(AI5="",0,AI5)),"") -> 9.24 | AK5: =IFERROR(IF(I5="","",IF(U5="",0,IF(V5="",(I5-AA5-AE5),MIN(AH5,(I5-AA5-AE5))))),"") -> 1.85 | AL5: =IFERROR(IF(I5="","",IF(V5="",0,MAX(0,(I5-AA5-AE5)-AK5))),"") -> 0
A6: B-2758 | B6: 46280 | H6: 3.81 | I6: =IFERROR(IF(H6="","",H6+AG6),"") -> 3.81 | J6: =IFERROR(IF(OR(I6="",AJ6=""),"",AJ6-(AK6+AL6)),"") -> 3.58 | K6: =IF(AND(AA6>0,AE6>0),TEXT(AA6,"0.000")&" kg "&Y6&" (funnel)"&" + "&TEXT(AE6,"0.000")&" kg "&AC6&" (funnel)",IF(AA6>0,TEXT(AA6,"0.000")&" kg "&Y6&" (funnel)",IF(AE6>0,TEXT(AE6,"0.000")&" kg "&AC6&" (funnel)",""))) | L6: =IF(OR(AK6="",AK6=0,U6=""),"",TEXT(AK6,"0.000")&" kg "&U6) -> 2.670 kg M1A- | M6: =IF(OR(AL6="",AL6=0,V6=""),"",TEXT(AL6,"0.000")&" kg "&V6) -> 1.140 kg M1B- | N6: =IF(OR(I6="",U6=""),"",TEXT(MAX(0,(AH6-AK6-IF(Y6=U6,AA6,0)-IF(AC6=U6,AE6,0))),"0.000")&" kg "&U6) -> 0.000 kg M1A- | O6: =IF(OR(I6="",V6=""),"",TEXT(MAX(0,(AI6-AL6-IF(Y6=V6,AA6,0)-IF(AC6=V6,AE6,0))),"0.000")&" kg "&V6) -> 3.580 kg M1B- | Q6: =IF($A6="","",IF(D6="",Q5,D6)) -> M1 | R6: =IF($A6="","",IF(E6="",R5,E6)) -> A | S6: =IF($A6="","",IF(F6="",S5,F6)) -> M1 | T6: =IF($A6="","",IF(G6="",T5,G6)) -> B | U6: =IF(OR(Q6="",R6=""),"",Q6&R6&"-") -> M1A- | V6: =IF(OR(S6="",T6=""),"",S6&T6&"-") -> M1B- | W6: =IF(AND(U6<>"",U5<>"",U6<>U5),1,0) -> 0 | X6: =IF(AND(V6<>"",V5<>"",V6<>V5),1,0) -> 0 | Y6: =IF(W6=1,U5,IF(AB5>0,Y5,"")) | Z6: =IF(W6=1,MAX(0,MIN(Settings!$B$6,(IFERROR(VLOOKUP(U5,'Bucket Status'!$A$4:$B$75,2,FALSE()),0)-(SUMIF($U$5:$U5,U5,$AK$5:$AK5)+SUMIF($V$5:$V5,U5,$AL$5:$AL5)+SUMIF($Y$5:$Y5,U5,$AA$5:$AA5)+SUMIF($AC$5:$AC5,U5,$AE$5:$AE5))))),IF(AB5>0,AB5,0)) -> 0 | AA6: =IFERROR(IF(I6="",0,MAX(0,MIN(Z6,I6))),0) -> 0 | AB6: =IFERROR(Z6-AA6,0) -> 0 | AC6: =IF(X6=1,V5,IF(AF5>0,AC5,"")) | AD6: =IF(X6=1,MAX(0,MIN(Settings!$B$6-Z6,(IFERROR(VLOOKUP(V5,'Bucket Status'!$A$4:$B$75,2,FALSE()),0)-(SUMIF($U$5:$U5,V5,$AK$5:$AK5)+SUMIF($V$5:$V5,V5,$AL$5:$AL5)+SUMIF($Y$5:$Y5,V5,$AA$5:$AA5)+SUMIF($AC$5:$AC5,V5,$AE$5:$AE5))))),IF(AF5>0,AF5,0)) -> 0 | AE6: =IFERROR(IF(I6="",0,MAX(0,MIN(AD6,I6-AA6))),0) -> 0 | AF6: =IFERROR(AD6-AE6,0) -> 0 | AG6: =IFERROR(IF(C6="Y",Settings!$B$4+Settings!$B$5,0),0) -> 0 | AH6: =IFERROR(IF(U6="","",IFERROR(VLOOKUP(U6,'Bucket Status'!$A$4:$B$75,2,FALSE()),0)-(SUMIF($U$5:$U5,U6,$AK$5:$AK5)+SUMIF($V$5:$V5,U6,$AL$5:$AL5)+SUMIF($Y$5:$Y5,U6,$AA$5:$AA5)+SUMIF($AC$5:$AC5,U6,$AE$5:$AE5))),"") -> 2.67 | AI6: =IFERROR(IF(V6="","",IFERROR(VLOOKUP(V6,'Bucket Status'!$A$4:$B$75,2,FALSE()),0)-(SUMIF($U$5:$U5,V6,$AK$5:$AK5)+SUMIF($V$5:$V5,V6,$AL$5:$AL5)+SUMIF($Y$5:$Y5,V6,$AA$5:$AA5)+SUMIF($AC$5:$AC5,V6,$AE$5:$AE5))),"") -> 4.72 | AJ6: =IFERROR(IF(AH6="","",AH6+IF(AI6="",0,AI6)),"") -> 7.39 | AK6: =IFERROR(IF(I6="","",IF(U6="",0,IF(V6="",(I6-AA6-AE6),MIN(AH6,(I6-AA6-AE6))))),"") -> 2.67 | AL6: =IFERROR(IF(I6="","",IF(V6="",0,MAX(0,(I6-AA6-AE6)-AK6))),"") -> 1.14
A7: B-2761 | B7: 46281 | D7: M1 | E7: C | F7: M1 | G7: D | H7: 5.31 | I7: =IFERROR(IF(H7="","",H7+AG7),"") -> 5.31 | J7: =IFERROR(IF(OR(I7="",AJ7=""),"",AJ7-(AK7+AL7)),"") -> 7.76 | K7: =IF(AND(AA7>0,AE7>0),TEXT(AA7,"0.000")&" kg "&Y7&" (funnel)"&" + "&TEXT(AE7,"0.000")&" kg "&AC7&" (funnel)",IF(AA7>0,TEXT(AA7,"0.000")&" kg "&Y7&" (funnel)",IF(AE7>0,TEXT(AE7,"0.000")&" kg "&AC7&" (funnel)",""))) -> 3.580 kg M1B- (funnel) | L7: =IF(OR(AK7="",AK7=0,U7=""),"",TEXT(AK7,"0.000")&" kg "&U7) -> 1.730 kg M1C- | M7: =IF(OR(AL7="",AL7=0,V7=""),"",TEXT(AL7,"0.000")&" kg "&V7) | N7: =IF(OR(I7="",U7=""),"",TEXT(MAX(0,(AH7-AK7-IF(Y7=U7,AA7,0)-IF(AC7=U7,AE7,0))),"0.000")&" kg "&U7) -> 2.900 kg M1C- | O7: =IF(OR(I7="",V7=""),"",TEXT(MAX(0,(AI7-AL7-IF(Y7=V7,AA7,0)-IF(AC7=V7,AE7,0))),"0.000")&" kg "&V7) -> 4.860 kg M1D- | Q7: =IF($A7="","",IF(D7="",Q6,D7)) -> M1 | R7: =IF($A7="","",IF(E7="",R6,E7)) -> C | S7: =IF($A7="","",IF(F7="",S6,F7)) -> M1 | T7: =IF($A7="","",IF(G7="",T6,G7)) -> D | U7: =IF(OR(Q7="",R7=""),"",Q7&R7&"-") -> M1C- | V7: =IF(OR(S7="",T7=""),"",S7&T7&"-") -> M1D- | W7: =IF(AND(U7<>"",U6<>"",U7<>U6),1,0) -> 1 | X7: =IF(AND(V7<>"",V6<>"",V7<>V6),1,0) -> 1 | Y7: =IF(W7=1,U6,IF(AB6>0,Y6,"")) -> M1A- | Z7: =IF(W7=1,MAX(0,MIN(Settings!$B$6,(IFERROR(VLOOKUP(U6,'Bucket Status'!$A$4:$B$75,2,FALSE()),0)-(SUMIF($U$5:$U6,U6,$AK$5:$AK6)+SUMIF($V$5:$V6,U6,$AL$5:$AL6)+SUMIF($Y$5:$Y6,U6,$AA$5:$AA6)+SUMIF($AC$5:$AC6,U6,$AE$5:$AE6))))),IF(AB6>0,AB6,0)) -> 0 | AA7: =IFERROR(IF(I7="",0,MAX(0,MIN(Z7,I7))),0) -> 0 | AB7: =IFERROR(Z7-AA7,0) -> 0 | AC7: =IF(X7=1,V6,IF(AF6>0,AC6,"")) -> M1B- | AD7: =IF(X7=1,MAX(0,MIN(Settings!$B$6-Z7,(IFERROR(VLOOKUP(V6,'Bucket Status'!$A$4:$B$75,2,FALSE()),0)-(SUMIF($U$5:$U6,V6,$AK$5:$AK6)+SUMIF($V$5:$V6,V6,$AL$5:$AL6)+SUMIF($Y$5:$Y6,V6,$AA$5:$AA6)+SUMIF($AC$5:$AC6,V6,$AE$5:$AE6))))),IF(AF6>0,AF6,0)) -> 3.58 | AE7: =IFERROR(IF(I7="",0,MAX(0,MIN(AD7,I7-AA7))),0) -> 3.58 | AF7: =IFERROR(AD7-AE7,0) -> 0 | AG7: =IFERROR(IF(C7="Y",Settings!$B$4+Settings!$B$5,0),0) -> 0 | AH7: =IFERROR(IF(U7="","",IFERROR(VLOOKUP(U7,'Bucket Status'!$A$4:$B$75,2,FALSE()),0)-(SUMIF($U$5:$U6,U7,$AK$5:$AK6)+SUMIF($V$5:$V6,U7,$AL$5:$AL6)+SUMIF($Y$5:$Y6,U7,$AA$5:$AA6)+SUMIF($AC$5:$AC6,U7,$AE$5:$AE6))),"") -> 4.63 | AI7: =IFERROR(IF(V7="","",IFERROR(VLOOKUP(V7,'Bucket Status'!$A$4:$B$75,2,FALSE()),0)-(SUMIF($U$5:$U6,V7,$AK$5:$AK6)+SUMIF($V$5:$V6,V7,$AL$5:$AL6)+SUMIF($Y$5:$Y6,V7,$AA$5:$AA6)+SUMIF($AC$5:$AC6,V7,$AE$5:$AE6))),"") -> 4.86 | AJ7: =IFERROR(IF(AH7="","",AH7+IF(AI7="",0,AI7)),"") -> 9.49 | AK7: =IFERROR(IF(I7="","",IF(U7="",0,IF(V7="",(I7-AA7-AE7),MIN(AH7,(I7-AA7-AE7))))),"") -> 1.73 | AL7: =IFERROR(IF(I7="","",IF(V7="",0,MAX(0,(I7-AA7-AE7)-AK7))),"") -> 0
A8: B-2762 | B8: 46282 | H8: 3.71 | I8: =IFERROR(IF(H8="","",H8+AG8),"") -> 3.71 | J8: =IFERROR(IF(OR(I8="",AJ8=""),"",AJ8-(AK8+AL8)),"") -> 4.05 | K8: =IF(AND(AA8>0,AE8>0),TEXT(AA8,"0.000")&" kg "&Y8&" (funnel)"&" + "&TEXT(AE8,"0.000")&" kg "&AC8&" (funnel)",IF(AA8>0,TEXT(AA8,"0.000")&" kg "&Y8&" (funnel)",IF(AE8>0,TEXT(AE8,"0.000")&" kg "&AC8&" (funnel)",""))) | L8: =IF(OR(AK8="",AK8=0,U8=""),"",TEXT(AK8,"0.000")&" kg "&U8) -> 2.900 kg M1C- | M8: =IF(OR(AL8="",AL8=0,V8=""),"",TEXT(AL8,"0.000")&" kg "&V8) -> 0.810 kg M1D- | N8: =IF(OR(I8="",U8=""),"",TEXT(MAX(0,(AH8-AK8-IF(Y8=U8,AA8,0)-IF(AC8=U8,AE8,0))),"0.000")&" kg "&U8) -> 0.000 kg M1C- | O8: =IF(OR(I8="",V8=""),"",TEXT(MAX(0,(AI8-AL8-IF(Y8=V8,AA8,0)-IF(AC8=V8,AE8,0))),"0.000")&" kg "&V8) -> 4.050 kg M1D- | Q8: =IF($A8="","",IF(D8="",Q7,D8)) -> M1 | R8: =IF($A8="","",IF(E8="",R7,E8)) -> C | S8: =IF($A8="","",IF(F8="",S7,F8)) -> M1 | T8: =IF($A8="","",IF(G8="",T7,G8)) -> D | U8: =IF(OR(Q8="",R8=""),"",Q8&R8&"-") -> M1C- | V8: =IF(OR(S8="",T8=""),"",S8&T8&"-") -> M1D- | W8: =IF(AND(U8<>"",U7<>"",U8<>U7),1,0) -> 0 | X8: =IF(AND(V8<>"",V7<>"",V8<>V7),1,0) -> 0 | Y8: =IF(W8=1,U7,IF(AB7>0,Y7,"")) | Z8: =IF(W8=1,MAX(0,MIN(Settings!$B$6,(IFERROR(VLOOKUP(U7,'Bucket Status'!$A$4:$B$75,2,FALSE()),0)-(SUMIF($U$5:$U7,U7,$AK$5:$AK7)+SUMIF($V$5:$V7,U7,$AL$5:$AL7)+SUMIF($Y$5:$Y7,U7,$AA$5:$AA7)+SUMIF($AC$5:$AC7,U7,$AE$5:$AE7))))),IF(AB7>0,AB7,0)) -> 0 | AA8: =IFERROR(IF(I8="",0,MAX(0,MIN(Z8,I8))),0) -> 0 | AB8: =IFERROR(Z8-AA8,0) -> 0 | AC8: =IF(X8=1,V7,IF(AF7>0,AC7,"")) | AD8: =IF(X8=1,MAX(0,MIN(Settings!$B$6-Z8,(IFERROR(VLOOKUP(V7,'Bucket Status'!$A$4:$B$75,2,FALSE()),0)-(SUMIF($U$5:$U7,V7,$AK$5:$AK7)+SUMIF($V$5:$V7,V7,$AL$5:$AL7)+SUMIF($Y$5:$Y7,V7,$AA$5:$AA7)+SUMIF($AC$5:$AC7,V7,$AE$5:$AE7))))),IF(AF7>0,AF7,0)) -> 0 | AE8: =IFERROR(IF(I8="",0,MAX(0,MIN(AD8,I8-AA8))),0) -> 0 | AF8: =IFERROR(AD8-AE8,0) -> 0 | AG8: =IFERROR(IF(C8="Y",Settings!$B$4+Settings!$B$5,0),0) -> 0 | AH8: =IFERROR(IF(U8="","",IFERROR(VLOOKUP(U8,'Bucket Status'!$A$4:$B$75,2,FALSE()),0)-(SUMIF($U$5:$U7,U8,$AK$5:$AK7)+SUMIF($V$5:$V7,U8,$AL$5:$AL7)+SUMIF($Y$5:$Y7,U8,$AA$5:$AA7)+SUMIF($AC$5:$AC7,U8,$AE$5:$AE7))),"") -> 2.9 | AI8: =IFERROR(IF(V8="","",IFERROR(VLOOKUP(V8,'Bucket Status'!$A$4:$B$75,2,FALSE()),0)-(SUMIF($U$5:$U7,V8,$AK$5:$AK7)+SUMIF($V$5:$V7,V8,$AL$5:$AL7)+SUMIF($Y$5:$Y7,V8,$AA$5:$AA7)+SUMIF($AC$5:$AC7,V8,$AE$5:$AE7))),"") -> 4.86 | AJ8: =IFERROR(IF(AH8="","",AH8+IF(AI8="",0,AI8)),"") -> 7.76 | AK8: =IFERROR(IF(I8="","",IF(U8="",0,IF(V8="",(I8-AA8-AE8),MIN(AH8,(I8-AA8-AE8))))),"") -> 2.9 | AL8: =IFERROR(IF(I8="","",IF(V8="",0,MAX(0,(I8-AA8-AE8)-AK8))),"") -> 0.81
A9: B-2762 | B9: 46283 | H9: 1.92 | I9: =IFERROR(IF(H9="","",H9+AG9),"") -> 1.92 | J9: =IFERROR(IF(OR(I9="",AJ9=""),"",AJ9-(AK9+AL9)),"") -> 2.13 | K9: =IF(AND(AA9>0,AE9>0),TEXT(AA9,"0.000")&" kg "&Y9&" (funnel)"&" + "&TEXT(AE9,"0.000")&" kg "&AC9&" (funnel)",IF(AA9>0,TEXT(AA9,"0.000")&" kg "&Y9&" (funnel)",IF(AE9>0,TEXT(AE9,"0.000")&" kg "&AC9&" (funnel)",""))) | L9: =IF(OR(AK9="",AK9=0,U9=""),"",TEXT(AK9,"0.000")&" kg "&U9) | M9: =IF(OR(AL9="",AL9=0,V9=""),"",TEXT(AL9,"0.000")&" kg "&V9) -> 1.920 kg M1D- | N9: =IF(OR(I9="",U9=""),"",TEXT(MAX(0,(AH9-AK9-IF(Y9=U9,AA9,0)-IF(AC9=U9,AE9,0))),"0.000")&" kg "&U9) -> 0.000 kg M1C- | O9: =IF(OR(I9="",V9=""),"",TEXT(MAX(0,(AI9-AL9-IF(Y9=V9,AA9,0)-IF(AC9=V9,AE9,0))),"0.000")&" kg "&V9) -> 2.130 kg M1D- | Q9: =IF($A9="","",IF(D9="",Q8,D9)) -> M1 | R9: =IF($A9="","",IF(E9="",R8,E9)) -> C | S9: =IF($A9="","",IF(F9="",S8,F9)) -> M1 | T9: =IF($A9="","",IF(G9="",T8,G9)) -> D | U9: =IF(OR(Q9="",R9=""),"",Q9&R9&"-") -> M1C- | V9: =IF(OR(S9="",T9=""),"",S9&T9&"-") -> M1D- | W9: =IF(AND(U9<>"",U8<>"",U9<>U8),1,0) -> 0 | X9: =IF(AND(V9<>"",V8<>"",V9<>V8),1,0) -> 0 | Y9: =IF(W9=1,U8,IF(AB8>0,Y8,"")) | Z9: =IF(W9=1,MAX(0,MIN(Settings!$B$6,(IFERROR(VLOOKUP(U8,'Bucket Status'!$A$4:$B$75,2,FALSE()),0)-(SUMIF($U$5:$U8,U8,$AK$5:$AK8)+SUMIF($V$5:$V8,U8,$AL$5:$AL8)+SUMIF($Y$5:$Y8,U8,$AA$5:$AA8)+SUMIF($AC$5:$AC8,U8,$AE$5:$AE8))))),IF(AB8>0,AB8,0)) -> 0 | AA9: =IFERROR(IF(I9="",0,MAX(0,MIN(Z9,I9))),0) -> 0 | AB9: =IFERROR(Z9-AA9,0) -> 0 | AC9: =IF(X9=1,V8,IF(AF8>0,AC8,"")) | AD9: =IF(X9=1,MAX(0,MIN(Settings!$B$6-Z9,(IFERROR(VLOOKUP(V8,'Bucket Status'!$A$4:$B$75,2,FALSE()),0)-(SUMIF($U$5:$U8,V8,$AK$5:$AK8)+SUMIF($V$5:$V8,V8,$AL$5:$AL8)+SUMIF($Y$5:$Y8,V8,$AA$5:$AA8)+SUMIF($AC$5:$AC8,V8,$AE$5:$AE8))))),IF(AF8>0,AF8,0)) -> 0 | AE9: =IFERROR(IF(I9="",0,MAX(0,MIN(AD9,I9-AA9))),0) -> 0 | AF9: =IFERROR(AD9-AE9,0) -> 0 | AG9: =IFERROR(IF(C9="Y",Settings!$B$4+Settings!$B$5,0),0) -> 0 | AH9: =IFERROR(IF(U9="","",IFERROR(VLOOKUP(U9,'Bucket Status'!$A$4:$B$75,2,FALSE()),0)-(SUMIF($U$5:$U8,U9,$AK$5:$AK8)+SUMIF($V$5:$V8,U9,$AL$5:$AL8)+SUMIF($Y$5:$Y8,U9,$AA$5:$AA8)+SUMIF($AC$5:$AC8,U9,$AE$5:$AE8))),"") -> 0 | AI9: =IFERROR(IF(V9="","",IFERROR(VLOOKUP(V9,'Bucket Status'!$A$4:$B$75,2,FALSE()),0)-(SUMIF($U$5:$U8,V9,$AK$5:$AK8)+SUMIF($V$5:$V8,V9,$AL$5:$AL8)+SUMIF($Y$5:$Y8,V9,$AA$5:$AA8)+SUMIF($AC$5:$AC8,V9,$AE$5:$AE8))),"") -> 4.05 | AJ9: =IFERROR(IF(AH9="","",AH9+IF(AI9="",0,AI9)),"") -> 4.05 | AK9: =IFERROR(IF(I9="","",IF(U9="",0,IF(V9="",(I9-AA9-AE9),MIN(AH9,(I9-AA9-AE9))))),"") -> 0 | AL9: =IFERROR(IF(I9="","",IF(V9="",0,MAX(0,(I9-AA9-AE9)-AK9))),"") -> 1.92
A10: B-2766 | B10: 46289 | H10: 1.5 | I10: =IFERROR(IF(H10="","",H10+AG10),"") -> 1.5 | J10: =IFERROR(IF(OR(I10="",AJ10=""),"",AJ10-(AK10+AL10)),"") -> 0.63 | K10: =IF(AND(AA10>0,AE10>0),TEXT(AA10,"0.000")&" kg "&Y10&" (funnel)"&" + "&TEXT(AE10,"0.000")&" kg "&AC10&" (funnel)",IF(AA10>0,TEXT(AA10,"0.000")&" kg "&Y10&" (funnel)",IF(AE10>0,TEXT(AE10,"0.000")&" kg "&AC10&" (funnel)",""))) | L10: =IF(OR(AK10="",AK10=0,U10=""),"",TEXT(AK10,"0.000")&" kg "&U10) | M10: =IF(OR(AL10="",AL10=0,V10=""),"",TEXT(AL10,"0.000")&" kg "&V10) -> 1.500 kg M1D- | N10: =IF(OR(I10="",U10=""),"",TEXT(MAX(0,(AH10-AK10-IF(Y10=U10,AA10,0)-IF(AC10=U10,AE10,0))),"0.000")&" kg "&U10) -> 0.000 kg M1C- | O10: =IF(OR(I10="",V10=""),"",TEXT(MAX(0,(AI10-AL10-IF(Y10=V10,AA10,0)-IF(AC10=V10,AE10,0))),"0.000")&" kg "&V10) -> 0.630 kg M1D- | P10: FAIL ADJUSTED USE | Q10: =IF($A10="","",IF(D10="",Q9,D10)) -> M1 | R10: =IF($A10="","",IF(E10="",R9,E10)) -> C | S10: =IF($A10="","",IF(F10="",S9,F10)) -> M1 | T10: =IF($A10="","",IF(G10="",T9,G10)) -> D | U10: =IF(OR(Q10="",R10=""),"",Q10&R10&"-") -> M1C- | V10: =IF(OR(S10="",T10=""),"",S10&T10&"-") -> M1D- | W10: =IF(AND(U10<>"",U9<>"",U10<>U9),1,0) -> 0 | X10: =IF(AND(V10<>"",V9<>"",V10<>V9),1,0) -> 0 | Y10: =IF(W10=1,U9,IF(AB9>0,Y9,"")) | Z10: =IF(W10=1,MAX(0,MIN(Settings!$B$6,(IFERROR(VLOOKUP(U9,'Bucket Status'!$A$4:$B$75,2,FALSE()),0)-(SUMIF($U$5:$U9,U9,$AK$5:$AK9)+SUMIF($V$5:$V9,U9,$AL$5:$AL9)+SUMIF($Y$5:$Y9,U9,$AA$5:$AA9)+SUMIF($AC$5:$AC9,U9,$AE$5:$AE9))))),IF(AB9>0,AB9,0)) -> 0 | AA10: =IFERROR(IF(I10="",0,MAX(0,MIN(Z10,I10))),0) -> 0 | AB10: =IFERROR(Z10-AA10,0) -> 0 | AC10: =IF(X10=1,V9,IF(AF9>0,AC9,"")) | AD10: =IF(X10=1,MAX(0,MIN(Settings!$B$6-Z10,(IFERROR(VLOOKUP(V9,'Bucket Status'!$A$4:$B$75,2,FALSE()),0)-(SUMIF($U$5:$U9,V9,$AK$5:$AK9)+SUMIF($V$5:$V9,V9,$AL$5:$AL9)+SUMIF($Y$5:$Y9,V9,$AA$5:$AA9)+SUMIF($AC$5:$AC9,V9,$AE$5:$AE9))))),IF(AF9>0,AF9,0)) -> 0 | AE10: =IFERROR(IF(I10="",0,MAX(0,MIN(AD10,I10-AA10))),0) -> 0 | AF10: =IFERROR(AD10-AE10,0) -> 0 | AG10: =IFERROR(IF(C10="Y",Settings!$B$4+Settings!$B$5,0),0) -> 0 | AH10: =IFERROR(IF(U10="","",IFERROR(VLOOKUP(U10,'Bucket Status'!$A$4:$B$75,2,FALSE()),0)-(SUMIF($U$5:$U9,U10,$AK$5:$AK9)+SUMIF($V$5:$V9,U10,$AL$5:$AL9)+SUMIF($Y$5:$Y9,U10,$AA$5:$AA9)+SUMIF($AC$5:$AC9,U10,$AE$5:$AE9))),"") -> 0 | AI10: =IFERROR(IF(V10="","",IFERROR(VLOOKUP(V10,'Bucket Status'!$A$4:$B$75,2,FALSE()),0)-(SUMIF($U$5:$U9,V10,$AK$5:$AK9)+SUMIF($V$5:$V9,V10,$AL$5:$AL9)+SUMIF($Y$5:$Y9,V10,$AA$5:$AA9)+SUMIF($AC$5:$AC9,V10,$AE$5:$AE9))),"") -> 2.13 | AJ10: =IFERROR(IF(AH10="","",AH10+IF(AI10="",0,AI10)),"") -> 2.13 | AK10: =IFERROR(IF(I10="","",IF(U10="",0,IF(V10="",(I10-AA10-AE10),MIN(AH10,(I10-AA10-AE10))))),"") -> 0 | AL10: =IFERROR(IF(I10="","",IF(V10="",0,MAX(0,(I10-AA10-AE10)-AK10))),"") -> 1.5
A11: B-2766 | B11: 46290 | D11: M2 | E11: A | F11: M2 | G11: B | H11: 2.5 | I11: =IFERROR(IF(H11="","",H11+AG11),"") -> 2.5 | J11: =IFERROR(IF(OR(I11="",AJ11=""),"",AJ11-(AK11+AL11)),"") -> 8.13 | K11: =IF(AND(AA11>0,AE11>0),TEXT(AA11,"0.000")&" kg "&Y11&" (funnel)"&" + "&TEXT(AE11,"0.000")&" kg "&AC11&" (funnel)",IF(AA11>0,TEXT(AA11,"0.000")&" kg "&Y11&" (funnel)",IF(AE11>0,TEXT(AE11,"0.000")&" kg "&AC11&" (funnel)",""))) -> 0.630 kg M1D- (funnel) | L11: =IF(OR(AK11="",AK11=0,U11=""),"",TEXT(AK11,"0.000")&" kg "&U11) -> 1.870 kg M2A- | M11: =IF(OR(AL11="",AL11=0,V11=""),"",TEXT(AL11,"0.000")&" kg "&V11) | N11: =IF(OR(I11="",U11=""),"",TEXT(MAX(0,(AH11-AK11-IF(Y11=U11,AA11,0)-IF(AC11=U11,AE11,0))),"0.000")&" kg "&U11) -> 3.180 kg M2A- | O11: =IF(OR(I11="",V11=""),"",TEXT(MAX(0,(AI11-AL11-IF(Y11=V11,AA11,0)-IF(AC11=V11,AE11,0))),"0.000")&" kg "&V11) -> 4.950 kg M2B- | Q11: =IF($A11="","",IF(D11="",Q10,D11)) -> M2 | R11: =IF($A11="","",IF(E11="",R10,E11)) -> A | S11: =IF($A11="","",IF(F11="",S10,F11)) -> M2 | T11: =IF($A11="","",IF(G11="",T10,G11)) -> B | U11: =IF(OR(Q11="",R11=""),"",Q11&R11&"-") -> M2A- | V11: =IF(OR(S11="",T11=""),"",S11&T11&"-") -> M2B- | W11: =IF(AND(U11<>"",U10<>"",U11<>U10),1,0) -> 1 | X11: =IF(AND(V11<>"",V10<>"",V11<>V10),1,0) -> 1 | Y11: =IF(W11=1,U10,IF(AB10>0,Y10,"")) -> M1C- | Z11: =IF(W11=1,MAX(0,MIN(Settings!$B$6,(IFERROR(VLOOKUP(U10,'Bucket Status'!$A$4:$B$75,2,FALSE()),0)-(SUMIF($U$5:$U10,U10,$AK$5:$AK10)+SUMIF($V$5:$V10,U10,$AL$5:$AL10)+SUMIF($Y$5:$Y10,U10,$AA$5:$AA10)+SUMIF($AC$5:$AC10,U10,$AE$5:$AE10))))),IF(AB10>0,AB10,0)) -> 0 | AA11: =IFERROR(IF(I11="",0,MAX(0,MIN(Z11,I11))),0) -> 0 | AB11: =IFERROR(Z11-AA11,0) -> 0 | AC11: =IF(X11=1,V10,IF(AF10>0,AC10,"")) -> M1D- | AD11: =IF(X11=1,MAX(0,MIN(Settings!$B$6-Z11,(IFERROR(VLOOKUP(V10,'Bucket Status'!$A$4:$B$75,2,FALSE()),0)-(SUMIF($U$5:$U10,V10,$AK$5:$AK10)+SUMIF($V$5:$V10,V10,$AL$5:$AL10)+SUMIF($Y$5:$Y10,V10,$AA$5:$AA10)+SUMIF($AC$5:$AC10,V10,$AE$5:$AE10))))),IF(AF10>0,AF10,0)) -> 0.63 | AE11: =IFERROR(IF(I11="",0,MAX(0,MIN(AD11,I11-AA11))),0) -> 0.63 | AF11: =IFERROR(AD11-AE11,0) -> 0 | AG11: =IFERROR(IF(C11="Y",Settings!$B$4+Settings!$B$5,0),0) -> 0 | AH11: =IFERROR(IF(U11="","",IFERROR(VLOOKUP(U11,'Bucket Status'!$A$4:$B$75,2,FALSE()),0)-(SUMIF($U$5:$U10,U11,$AK$5:$AK10)+SUMIF($V$5:$V10,U11,$AL$5:$AL10)+SUMIF($Y$5:$Y10,U11,$AA$5:$AA10)+SUMIF($AC$5:$AC10,U11,$AE$5:$AE10))),"") -> 5.05 | AI11: =IFERROR(IF(V11="","",IFERROR(VLOOKUP(V11,'Bucket Status'!$A$4:$B$75,2,FALSE()),0)-(SUMIF($U$5:$U10,V11,$AK$5:$AK10)+SUMIF($V$5:$V10,V11,$AL$5:$AL10)+SUMIF($Y$5:$Y10,V11,$AA$5:$AA10)+SUMIF($AC$5:$AC10,V11,$AE$5:$AE10))),"") -> 4.95 | AJ11: =IFERROR(IF(AH11="","",AH11+IF(AI11="",0,AI11)),"") -> 10 | AK11: =IFERROR(IF(I11="","",IF(U11="",0,IF(V11="",(I11-AA11-AE11),MIN(AH11,(I11-AA11-AE11))))),"") -> 1.87 | AL11: =IFERROR(IF(I11="","",IF(V11="",0,MAX(0,(I11-AA11-AE11)-AK11))),"") -> 0
A12: B-2769 | B12: 46293 | H12: 3.97 | I12: =IFERROR(IF(H12="","",H12+AG12),"") -> 3.97 | J12: =IFERROR(IF(OR(I12="",AJ12=""),"",AJ12-(AK12+AL12)),"") -> 4.16 | K12: =IF(AND(AA12>0,AE12>0),TEXT(AA12,"0.000")&" kg "&Y12&" (funnel)"&" + "&TEXT(AE12,"0.000")&" kg "&AC12&" (funnel)",IF(AA12>0,TEXT(AA12,"0.000")&" kg "&Y12&" (funnel)",IF(AE12>0,TEXT(AE12,"0.000")&" kg "&AC12&" (funnel)",""))) | L12: =IF(OR(AK12="",AK12=0,U12=""),"",TEXT(AK12,"0.000")&" kg "&U12) -> 3.180 kg M2A- | M12: =IF(OR(AL12="",AL12=0,V12=""),"",TEXT(AL12,"0.000")&" kg "&V12) -> 0.790 kg M2B- | N12: =IF(OR(I12="",U12=""),"",TEXT(MAX(0,(AH12-AK12-IF(Y12=U12,AA12,0)-IF(AC12=U12,AE12,0))),"0.000")&" kg "&U12) -> 0.000 kg M2A- | O12: =IF(OR(I12="",V12=""),"",TEXT(MAX(0,(AI12-AL12-IF(Y12=V12,AA12,0)-IF(AC12=V12,AE12,0))),"0.000")&" kg "&V12) -> 4.160 kg M2B- | Q12: =IF($A12="","",IF(D12="",Q11,D12)) -> M2 | R12: =IF($A12="","",IF(E12="",R11,E12)) -> A | S12: =IF($A12="","",IF(F12="",S11,F12)) -> M2 | T12: =IF($A12="","",IF(G12="",T11,G12)) -> B | U12: =IF(OR(Q12="",R12=""),"",Q12&R12&"-") -> M2A- | V12: =IF(OR(S12="",T12=""),"",S12&T12&"-") -> M2B- | W12: =IF(AND(U12<>"",U11<>"",U12<>U11),1,0) -> 0 | X12: =IF(AND(V12<>"",V11<>"",V12<>V11),1,0) -> 0 | Y12: =IF(W12=1,U11,IF(AB11>0,Y11,"")) | Z12: =IF(W12=1,MAX(0,MIN(Settings!$B$6,(IFERROR(VLOOKUP(U11,'Bucket Status'!$A$4:$B$75,2,FALSE()),0)-(SUMIF($U$5:$U11,U11,$AK$5:$AK11)+SUMIF($V$5:$V11,U11,$AL$5:$AL11)+SUMIF($Y$5:$Y11,U11,$AA$5:$AA11)+SUMIF($AC$5:$AC11,U11,$AE$5:$AE11))))),IF(AB11>0,AB11,0)) -> 0 | AA12: =IFERROR(IF(I12="",0,MAX(0,MIN(Z12,I12))),0) -> 0 | AB12: =IFERROR(Z12-AA12,0) -> 0 | AC12: =IF(X12=1,V11,IF(AF11>0,AC11,"")) | AD12: =IF(X12=1,MAX(0,MIN(Settings!$B$6-Z12,(IFERROR(VLOOKUP(V11,'Bucket Status'!$A$4:$B$75,2,FALSE()),0)-(SUMIF($U$5:$U11,V11,$AK$5:$AK11)+SUMIF($V$5:$V11,V11,$AL$5:$AL11)+SUMIF($Y$5:$Y11,V11,$AA$5:$AA11)+SUMIF($AC$5:$AC11,V11,$AE$5:$AE11))))),IF(AF11>0,AF11,0)) -> 0 | AE12: =IFERROR(IF(I12="",0,MAX(0,MIN(AD12,I12-AA12))),0) -> 0 | AF12: =IFERROR(AD12-AE12,0) -> 0 | AG12: =IFERROR(IF(C12="Y",Settings!$B$4+Settings!$B$5,0),0) -> 0 | AH12: =IFERROR(IF(U12="","",IFERROR(VLOOKUP(U12,'Bucket Status'!$A$4:$B$75,2,FALSE()),0)-(SUMIF($U$5:$U11,U12,$AK$5:$AK11)+SUMIF($V$5:$V11,U12,$AL$5:$AL11)+SUMIF($Y$5:$Y11,U12,$AA$5:$AA11)+SUMIF($AC$5:$AC11,U12,$AE$5:$AE11))),"") -> 3.18 | AI12: =IFERROR(IF(V12="","",IFERROR(VLOOKUP(V12,'Bucket Status'!$A$4:$B$75,2,FALSE()),0)-(SUMIF($U$5:$U11,V12,$AK$5:$AK11)+SUMIF($V$5:$V11,V12,$AL$5:$AL11)+SUMIF($Y$5:$Y11,V12,$AA$5:$AA11)+SUMIF($AC$5:$AC11,V12,$AE$5:$AE11))),"") -> 4.95 | AJ12: =IFERROR(IF(AH12="","",AH12+IF(AI12="",0,AI12)),"") -> 8.13 | AK12: =IFERROR(IF(I12="","",IF(U12="",0,IF(V12="",(I12-AA12-AE12),MIN(AH12,(I12-AA12-AE12))))),"") -> 3.18 | AL12: =IFERROR(IF(I12="","",IF(V12="",0,MAX(0,(I12-AA12-AE12)-AK12))),"") -> 0.79
A13: B-2772 | B13: 46295 | H13: 2.2 | I13: =IFERROR(IF(H13="","",H13+AG13),"") -> 2.2 | J13: =IFERROR(IF(OR(I13="",AJ13=""),"",AJ13-(AK13+AL13)),"") -> 1.96 | K13: =IF(AND(AA13>0,AE13>0),TEXT(AA13,"0.000")&" kg "&Y13&" (funnel)"&" + "&TEXT(AE13,"0.000")&" kg "&AC13&" (funnel)",IF(AA13>0,TEXT(AA13,"0.000")&" kg "&Y13&" (funnel)",IF(AE13>0,TEXT(AE13,"0.000")&" kg "&AC13&" (funnel)",""))) | L13: =IF(OR(AK13="",AK13=0,U13=""),"",TEXT(AK13,"0.000")&" kg "&U13) | M13: =IF(OR(AL13="",AL13=0,V13=""),"",TEXT(AL13,"0.000")&" kg "&V13) -> 2.200 kg M2B- | N13: =IF(OR(I13="",U13=""),"",TEXT(MAX(0,(AH13-AK13-IF(Y13=U13,AA13,0)-IF(AC13=U13,AE13,0))),"0.000")&" kg "&U13) -> 0.000 kg M2A- | O13: =IF(OR(I13="",V13=""),"",TEXT(MAX(0,(AI13-AL13-IF(Y13=V13,AA13,0)-IF(AC13=V13,AE13,0))),"0.000")&" kg "&V13) -> 1.960 kg M2B- | Q13: =IF($A13="","",IF(D13="",Q12,D13)) -> M2 | R13: =IF($A13="","",IF(E13="",R12,E13)) -> A | S13: =IF($A13="","",IF(F13="",S12,F13)) -> M2 | T13: =IF($A13="","",IF(G13="",T12,G13)) -> B | U13: =IF(OR(Q13="",R13=""),"",Q13&R13&"-") -> M2A- | V13: =IF(OR(S13="",T13=""),"",S13&T13&"-") -> M2B- | W13: =IF(AND(U13<>"",U12<>"",U13<>U12),1,0) -> 0 | X13: =IF(AND(V13<>"",V12<>"",V13<>V12),1,0) -> 0 | Y13: =IF(W13=1,U12,IF(AB12>0,Y12,"")) | Z13: =IF(W13=1,MAX(0,MIN(Settings!$B$6,(IFERROR(VLOOKUP(U12,'Bucket Status'!$A$4:$B$75,2,FALSE()),0)-(SUMIF($U$5:$U12,U12,$AK$5:$AK12)+SUMIF($V$5:$V12,U12,$AL$5:$AL12)+SUMIF($Y$5:$Y12,U12,$AA$5:$AA12)+SUMIF($AC$5:$AC12,U12,$AE$5:$AE12))))),IF(AB12>0,AB12,0)) -> 0 | AA13: =IFERROR(IF(I13="",0,MAX(0,MIN(Z13,I13))),0) -> 0 | AB13: =IFERROR(Z13-AA13,0) -> 0 | AC13: =IF(X13=1,V12,IF(AF12>0,AC12,"")) | AD13: =IF(X13=1,MAX(0,MIN(Settings!$B$6-Z13,(IFERROR(VLOOKUP(V12,'Bucket Status'!$A$4:$B$75,2,FALSE()),0)-(SUMIF($U$5:$U12,V12,$AK$5:$AK12)+SUMIF($V$5:$V12,V12,$AL$5:$AL12)+SUMIF($Y$5:$Y12,V12,$AA$5:$AA12)+SUMIF($AC$5:$AC12,V12,$AE$5:$AE12))))),IF(AF12>0,AF12,0)) -> 0 | AE13: =IFERROR(IF(I13="",0,MAX(0,MIN(AD13,I13-AA13))),0) -> 0 | AF13: =IFERROR(AD13-AE13,0) -> 0 | AG13: =IFERROR(IF(C13="Y",Settings!$B$4+Settings!$B$5,0),0) -> 0 | AH13: =IFERROR(IF(U13="","",IFERROR(VLOOKUP(U13,'Bucket Status'!$A$4:$B$75,2,FALSE()),0)-(SUMIF($U$5:$U12,U13,$AK$5:$AK12)+SUMIF($V$5:$V12,U13,$AL$5:$AL12)+SUMIF($Y$5:$Y12,U13,$AA$5:$AA12)+SUMIF($AC$5:$AC12,U13,$AE$5:$AE12))),"") -> 0 | AI13: =IFERROR(IF(V13="","",IFERROR(VLOOKUP(V13,'Bucket Status'!$A$4:$B$75,2,FALSE()),0)-(SUMIF($U$5:$U12,V13,$AK$5:$AK12)+SUMIF($V$5:$V12,V13,$AL$5:$AL12)+SUMIF($Y$5:$Y12,V13,$AA$5:$AA12)+SUMIF($AC$5:$AC12,V13,$AE$5:$AE12))),"") -> 4.16 | AJ13: =IFERROR(IF(AH13="","",AH13+IF(AI13="",0,AI13)),"") -> 4.16 | AK13: =IFERROR(IF(I13="","",IF(U13="",0,IF(V13="",(I13-AA13-AE13),MIN(AH13,(I13-AA13-AE13))))),"") -> 0 | AL13: =IFERROR(IF(I13="","",IF(V13="",0,MAX(0,(I13-AA13-AE13)-AK13))),"") -> 2.2
A14: B-2775 | B14: 46297 | D14: M2 | E14: C | H14: 3.6 | I14: =IFERROR(IF(H14="","",H14+AG14),"") -> 3.6 | J14: =IFERROR(IF(OR(I14="",AJ14=""),"",AJ14-(AK14+AL14)),"") -> 3.45 | K14: =IF(AND(AA14>0,AE14>0),TEXT(AA14,"0.000")&" kg "&Y14&" (funnel)"&" + "&TEXT(AE14,"0.000")&" kg "&AC14&" (funnel)",IF(AA14>0,TEXT(AA14,"0.000")&" kg "&Y14&" (funnel)",IF(AE14>0,TEXT(AE14,"0.000")&" kg "&AC14&" (funnel)",""))) | L14: =IF(OR(AK14="",AK14=0,U14=""),"",TEXT(AK14,"0.000")&" kg "&U14) -> 3.600 kg M2C- | M14: =IF(OR(AL14="",AL14=0,V14=""),"",TEXT(AL14,"0.000")&" kg "&V14) | N14: =IF(OR(I14="",U14=""),"",TEXT(MAX(0,(AH14-AK14-IF(Y14=U14,AA14,0)-IF(AC14=U14,AE14,0))),"0.000")&" kg "&U14) -> 1.490 kg M2C- | O14: =IF(OR(I14="",V14=""),"",TEXT(MAX(0,(AI14-AL14-IF(Y14=V14,AA14,0)-IF(AC14=V14,AE14,0))),"0.000")&" kg "&V14) -> 1.960 kg M2B- | Q14: =IF($A14="","",IF(D14="",Q13,D14)) -> M2 | R14: =IF($A14="","",IF(E14="",R13,E14)) -> C | S14: =IF($A14="","",IF(F14="",S13,F14)) -> M2 | T14: =IF($A14="","",IF(G14="",T13,G14)) -> B | U14: =IF(OR(Q14="",R14=""),"",Q14&R14&"-") -> M2C- | V14: =IF(OR(S14="",T14=""),"",S14&T14&"-") -> M2B- | W14: =IF(AND(U14<>"",U13<>"",U14<>U13),1,0) -> 1 | X14: =IF(AND(V14<>"",V13<>"",V14<>V13),1,0) -> 0 | Y14: =IF(W14=1,U13,IF(AB13>0,Y13,"")) -> M2A- | Z14: =IF(W14=1,MAX(0,MIN(Settings!$B$6,(IFERROR(VLOOKUP(U13,'Bucket Status'!$A$4:$B$75,2,FALSE()),0)-(SUMIF($U$5:$U13,U13,$AK$5:$AK13)+SUMIF($V$5:$V13,U13,$AL$5:$AL13)+SUMIF($Y$5:$Y13,U13,$AA$5:$AA13)+SUMIF($AC$5:$AC13,U13,$AE$5:$AE13))))),IF(AB13>0,AB13,0)) -> 0 | AA14: =IFERROR(IF(I14="",0,MAX(0,MIN(Z14,I14))),0) -> 0 | AB14: =IFERROR(Z14-AA14,0) -> 0 | AC14: =IF(X14=1,V13,IF(AF13>0,AC13,"")) | AD14: =IF(X14=1,MAX(0,MIN(Settings!$B$6-Z14,(IFERROR(VLOOKUP(V13,'Bucket Status'!$A$4:$B$75,2,FALSE()),0)-(SUMIF($U$5:$U13,V13,$AK$5:$AK13)+SUMIF($V$5:$V13,V13,$AL$5:$AL13)+SUMIF($Y$5:$Y13,V13,$AA$5:$AA13)+SUMIF($AC$5:$AC13,V13,$AE$5:$AE13))))),IF(AF13>0,AF13,0)) -> 0 | AE14: =IFERROR(IF(I14="",0,MAX(0,MIN(AD14,I14-AA14))),0) -> 0 | AF14: =IFERROR(AD14-AE14,0) -> 0 | AG14: =IFERROR(IF(C14="Y",Settings!$B$4+Settings!$B$5,0),0) -> 0 | AH14: =IFERROR(IF(U14="","",IFERROR(VLOOKUP(U14,'Bucket Status'!$A$4:$B$75,2,FALSE()),0)-(SUMIF($U$5:$U13,U14,$AK$5:$AK13)+SUMIF($V$5:$V13,U14,$AL$5:$AL13)+SUMIF($Y$5:$Y13,U14,$AA$5:$AA13)+SUMIF($AC$5:$AC13,U14,$AE$5:$AE13))),"") -> 5.09 | AI14: =IFERROR(IF(V14="","",IFERROR(VLOOKUP(V14,'Bucket Status'!$A$4:$B$75,2,FALSE()),0)-(SUMIF($U$5:$U13,V14,$AK$5:$AK13)+SUMIF($V$5:$V13,V14,$AL$5:$AL13)+SUMIF($Y$5:$Y13,V14,$AA$5:$AA13)+SUMIF($AC$5:$AC13,V14,$AE$5:$AE13))),"") -> 1.96 | AJ14: =IFERROR(IF(AH14="","",AH14+IF(AI14="",0,AI14)),"") -> 7.05 | AK14: =IFERROR(IF(I14="","",IF(U14="",0,IF(V14="",(I14-AA14-AE14),MIN(AH14,(I14-AA14-AE14))))),"") -> 3.6 | AL14: =IFERROR(IF(I14="","",IF(V14="",0,MAX(0,(I14-AA14-AE14)-AK14))),"") -> 0
A15: B-2778 | B15: 46300 | F15: M2 | G15: D | H15: 4.24 | I15: =IFERROR(IF(H15="","",H15+AG15),"") -> 4.24 | J15: =IFERROR(IF(OR(I15="",AJ15=""),"",AJ15-(AK15+AL15)),"") -> 3.99 | K15: =IF(AND(AA15>0,AE15>0),TEXT(AA15,"0.000")&" kg "&Y15&" (funnel)"&" + "&TEXT(AE15,"0.000")&" kg "&AC15&" (funnel)",IF(AA15>0,TEXT(AA15,"0.000")&" kg "&Y15&" (funnel)",IF(AE15>0,TEXT(AE15,"0.000")&" kg "&AC15&" (funnel)",""))) -> 1.960 kg M2B- (funnel) | L15: =IF(OR(AK15="",AK15=0,U15=""),"",TEXT(AK15,"0.000")&" kg "&U15) -> 1.490 kg M2C- | M15: =IF(OR(AL15="",AL15=0,V15=""),"",TEXT(AL15,"0.000")&" kg "&V15) -> 0.790 kg M2D- | N15: =IF(OR(I15="",U15=""),"",TEXT(MAX(0,(AH15-AK15-IF(Y15=U15,AA15,0)-IF(AC15=U15,AE15,0))),"0.000")&" kg "&U15) -> 0.000 kg M2C- | O15: =IF(OR(I15="",V15=""),"",TEXT(MAX(0,(AI15-AL15-IF(Y15=V15,AA15,0)-IF(AC15=V15,AE15,0))),"0.000")&" kg "&V15) -> 3.990 kg M2D- | Q15: =IF($A15="","",IF(D15="",Q14,D15)) -> M2 | R15: =IF($A15="","",IF(E15="",R14,E15)) -> C | S15: =IF($A15="","",IF(F15="",S14,F15)) -> M2 | T15: =IF($A15="","",IF(G15="",T14,G15)) -> D | U15: =IF(OR(Q15="",R15=""),"",Q15&R15&"-") -> M2C- | V15: =IF(OR(S15="",T15=""),"",S15&T15&"-") -> M2D- | W15: =IF(AND(U15<>"",U14<>"",U15<>U14),1,0) -> 0 | X15: =IF(AND(V15<>"",V14<>"",V15<>V14),1,0) -> 1 | Y15: =IF(W15=1,U14,IF(AB14>0,Y14,"")) | Z15: =IF(W15=1,MAX(0,MIN(Settings!$B$6,(IFERROR(VLOOKUP(U14,'Bucket Status'!$A$4:$B$75,2,FALSE()),0)-(SUMIF($U$5:$U14,U14,$AK$5:$AK14)+SUMIF($V$5:$V14,U14,$AL$5:$AL14)+SUMIF($Y$5:$Y14,U14,$AA$5:$AA14)+SUMIF($AC$5:$AC14,U14,$AE$5:$AE14))))),IF(AB14>0,AB14,0)) -> 0 | AA15: =IFERROR(IF(I15="",0,MAX(0,MIN(Z15,I15))),0) -> 0 | AB15: =IFERROR(Z15-AA15,0) -> 0 | AC15: =IF(X15=1,V14,IF(AF14>0,AC14,"")) -> M2B- | AD15: =IF(X15=1,MAX(0,MIN(Settings!$B$6-Z15,(IFERROR(VLOOKUP(V14,'Bucket Status'!$A$4:$B$75,2,FALSE()),0)-(SUMIF($U$5:$U14,V14,$AK$5:$AK14)+SUMIF($V$5:$V14,V14,$AL$5:$AL14)+SUMIF($Y$5:$Y14,V14,$AA$5:$AA14)+SUMIF($AC$5:$AC14,V14,$AE$5:$AE14))))),IF(AF14>0,AF14,0)) -> 1.96 | AE15: =IFERROR(IF(I15="",0,MAX(0,MIN(AD15,I15-AA15))),0) -> 1.96 | AF15: =IFERROR(AD15-AE15,0) -> 0 | AG15: =IFERROR(IF(C15="Y",Settings!$B$4+Settings!$B$5,0),0) -> 0 | AH15: =IFERROR(IF(U15="","",IFERROR(VLOOKUP(U15,'Bucket Status'!$A$4:$B$75,2,FALSE()),0)-(SUMIF($U$5:$U14,U15,$AK$5:$AK14)+SUMIF($V$5:$V14,U15,$AL$5:$AL14)+SUMIF($Y$5:$Y14,U15,$AA$5:$AA14)+SUMIF($AC$5:$AC14,U15,$AE$5:$AE14))),"") -> 1.49 | AI15: =IFERROR(IF(V15="","",IFERROR(VLOOKUP(V15,'Bucket Status'!$A$4:$B$75,2,FALSE()),0)-(SUMIF($U$5:$U14,V15,$AK$5:$AK14)+SUMIF($V$5:$V14,V15,$AL$5:$AL14)+SUMIF($Y$5:$Y14,V15,$AA$5:$AA14)+SUMIF($AC$5:$AC14,V15,$AE$5:$AE14))),"") -> 4.78 | AJ15: =IFERROR(IF(AH15="","",AH15+IF(AI15="",0,AI15)),"") -> 6.27 | AK15: =IFERROR(IF(I15="","",IF(U15="",0,IF(V15="",(I15-AA15-AE15),MIN(AH15,(I15-AA15-AE15))))),"") -> 1.49 | AL15: =IFERROR(IF(I15="","",IF(V15="",0,MAX(0,(I15-AA15-AE15)-AK15))),"") -> 0.79
A16: B-2781 | B16: 46301 | D16: M3 | E16: A | H16: 3.5 | I16: =IFERROR(IF(H16="","",H16+AG16),"") -> 3.5 | J16: =IFERROR(IF(OR(I16="",AJ16=""),"",AJ16-(AK16+AL16)),"") -> 5.49 | K16: =IF(AND(AA16>0,AE16>0),TEXT(AA16,"0.000")&" kg "&Y16&" (funnel)"&" + "&TEXT(AE16,"0.000")&" kg "&AC16&" (funnel)",IF(AA16>0,TEXT(AA16,"0.000")&" kg "&Y16&" (funnel)",IF(AE16>0,TEXT(AE16,"0.000")&" kg "&AC16&" (funnel)",""))) | L16: =IF(OR(AK16="",AK16=0,U16=""),"",TEXT(AK16,"0.000")&" kg "&U16) -> 3.500 kg M3A- | M16: =IF(OR(AL16="",AL16=0,V16=""),"",TEXT(AL16,"0.000")&" kg "&V16) | N16: =IF(OR(I16="",U16=""),"",TEXT(MAX(0,(AH16-AK16-IF(Y16=U16,AA16,0)-IF(AC16=U16,AE16,0))),"0.000")&" kg "&U16) -> 1.500 kg M3A- | O16: =IF(OR(I16="",V16=""),"",TEXT(MAX(0,(AI16-AL16-IF(Y16=V16,AA16,0)-IF(AC16=V16,AE16,0))),"0.000")&" kg "&V16) -> 3.990 kg M2D- | Q16: =IF($A16="","",IF(D16="",Q15,D16)) -> M3 | R16: =IF($A16="","",IF(E16="",R15,E16)) -> A | S16: =IF($A16="","",IF(F16="",S15,F16)) -> M2 | T16: =IF($A16="","",IF(G16="",T15,G16)) -> D | U16: =IF(OR(Q16="",R16=""),"",Q16&R16&"-") -> M3A- | V16: =IF(OR(S16="",T16=""),"",S16&T16&"-") -> M2D- | W16: =IF(AND(U16<>"",U15<>"",U16<>U15),1,0) -> 1 | X16: =IF(AND(V16<>"",V15<>"",V16<>V15),1,0) -> 0 | Y16: =IF(W16=1,U15,IF(AB15>0,Y15,"")) -> M2C- | Z16: =IF(W16=1,MAX(0,MIN(Settings!$B$6,(IFERROR(VLOOKUP(U15,'Bucket Status'!$A$4:$B$75,2,FALSE()),0)-(SUMIF($U$5:$U15,U15,$AK$5:$AK15)+SUMIF($V$5:$V15,U15,$AL$5:$AL15)+SUMIF($Y$5:$Y15,U15,$AA$5:$AA15)+SUMIF($AC$5:$AC15,U15,$AE$5:$AE15))))),IF(AB15>0,AB15,0)) -> 0 | AA16: =IFERROR(IF(I16="",0,MAX(0,MIN(Z16,I16))),0) -> 0 | AB16: =IFERROR(Z16-AA16,0) -> 0 | AC16: =IF(X16=1,V15,IF(AF15>0,AC15,"")) | AD16: =IF(X16=1,MAX(0,MIN(Settings!$B$6-Z16,(IFERROR(VLOOKUP(V15,'Bucket Status'!$A$4:$B$75,2,FALSE()),0)-(SUMIF($U$5:$U15,V15,$AK$5:$AK15)+SUMIF($V$5:$V15,V15,$AL$5:$AL15)+SUMIF($Y$5:$Y15,V15,$AA$5:$AA15)+SUMIF($AC$5:$AC15,V15,$AE$5:$AE15))))),IF(AF15>0,AF15,0)) -> 0 | AE16: =IFERROR(IF(I16="",0,MAX(0,MIN(AD16,I16-AA16))),0) -> 0 | AF16: =IFERROR(AD16-AE16,0) -> 0 | AG16: =IFERROR(IF(C16="Y",Settings!$B$4+Settings!$B$5,0),0) -> 0 | AH16: =IFERROR(IF(U16="","",IFERROR(VLOOKUP(U16,'Bucket Status'!$A$4:$B$75,2,FALSE()),0)-(SUMIF($U$5:$U15,U16,$AK$5:$AK15)+SUMIF($V$5:$V15,U16,$AL$5:$AL15)+SUMIF($Y$5:$Y15,U16,$AA$5:$AA15)+SUMIF($AC$5:$AC15,U16,$AE$5:$AE15))),"") -> 5 | AI16: =IFERROR(IF(V16="","",IFERROR(VLOOKUP(V16,'Bucket Status'!$A$4:$B$75,2,FALSE()),0)-(SUMIF($U$5:$U15,V16,$AK$5:$AK15)+SUMIF($V$5:$V15,V16,$AL$5:$AL15)+SUMIF($Y$5:$Y15,V16,$AA$5:$AA15)+SUMIF($AC$5:$AC15,V16,$AE$5:$AE15))),"") -> 3.99 | AJ16: =IFERROR(IF(AH16="","",AH16+IF(AI16="",0,AI16)),"") -> 8.99 | AK16: =IFERROR(IF(I16="","",IF(U16="",0,IF(V16="",(I16-AA16-AE16),MIN(AH16,(I16-AA16-AE16))))),"") -> 3.5 | AL16: =IFERROR(IF(I16="","",IF(V16="",0,MAX(0,(I16-AA16-AE16)-AK16))),"") -> 0
A17: B-2784 | B17: 46302 | H17: 3.72 | I17: =IFERROR(IF(H17="","",H17+AG17),"") -> 3.72 | J17: =IFERROR(IF(OR(I17="",AJ17=""),"",AJ17-(AK17+AL17)),"") -> 1.77 | K17: =IF(AND(AA17>0,AE17>0),TEXT(AA17,"0.000")&" kg "&Y17&" (funnel)"&" + "&TEXT(AE17,"0.000")&" kg "&AC17&" (funnel)",IF(AA17>0,TEXT(AA17,"0.000")&" kg "&Y17&" (funnel)",IF(AE17>0,TEXT(AE17,"0.000")&" kg "&AC17&" (funnel)",""))) | L17: =IF(OR(AK17="",AK17=0,U17=""),"",TEXT(AK17,"0.000")&" kg "&U17) -> 1.500 kg M3A- | M17: =IF(OR(AL17="",AL17=0,V17=""),"",TEXT(AL17,"0.000")&" kg "&V17) -> 2.220 kg M2D- | N17: =IF(OR(I17="",U17=""),"",TEXT(MAX(0,(AH17-AK17-IF(Y17=U17,AA17,0)-IF(AC17=U17,AE17,0))),"0.000")&" kg "&U17) -> 0.000 kg M3A- | O17: =IF(OR(I17="",V17=""),"",TEXT(MAX(0,(AI17-AL17-IF(Y17=V17,AA17,0)-IF(AC17=V17,AE17,0))),"0.000")&" kg "&V17) -> 1.770 kg M2D- | Q17: =IF($A17="","",IF(D17="",Q16,D17)) -> M3 | R17: =IF($A17="","",IF(E17="",R16,E17)) -> A | S17: =IF($A17="","",IF(F17="",S16,F17)) -> M2 | T17: =IF($A17="","",IF(G17="",T16,G17)) -> D | U17: =IF(OR(Q17="",R17=""),"",Q17&R17&"-") -> M3A- | V17: =IF(OR(S17="",T17=""),"",S17&T17&"-") -> M2D- | W17: =IF(AND(U17<>"",U16<>"",U17<>U16),1,0) -> 0 | X17: =IF(AND(V17<>"",V16<>"",V17<>V16),1,0) -> 0 | Y17: =IF(W17=1,U16,IF(AB16>0,Y16,"")) | Z17: =IF(W17=1,MAX(0,MIN(Settings!$B$6,(IFERROR(VLOOKUP(U16,'Bucket Status'!$A$4:$B$75,2,FALSE()),0)-(SUMIF($U$5:$U16,U16,$AK$5:$AK16)+SUMIF($V$5:$V16,U16,$AL$5:$AL16)+SUMIF($Y$5:$Y16,U16,$AA$5:$AA16)+SUMIF($AC$5:$AC16,U16,$AE$5:$AE16))))),IF(AB16>0,AB16,0)) -> 0 | AA17: =IFERROR(IF(I17="",0,MAX(0,MIN(Z17,I17))),0) -> 0 | AB17: =IFERROR(Z17-AA17,0) -> 0 | AC17: =IF(X17=1,V16,IF(AF16>0,AC16,"")) | AD17: =IF(X17=1,MAX(0,MIN(Settings!$B$6-Z17,(IFERROR(VLOOKUP(V16,'Bucket Status'!$A$4:$B$75,2,FALSE()),0)-(SUMIF($U$5:$U16,V16,$AK$5:$AK16)+SUMIF($V$5:$V16,V16,$AL$5:$AL16)+SUMIF($Y$5:$Y16,V16,$AA$5:$AA16)+SUMIF($AC$5:$AC16,V16,$AE$5:$AE16))))),IF(AF16>0,AF16,0)) -> 0 | AE17: =IFERROR(IF(I17="",0,MAX(0,MIN(AD17,I17-AA17))),0) -> 0 | AF17: =IFERROR(AD17-AE17,0) -> 0 | AG17: =IFERROR(IF(C17="Y",Settings!$B$4+Settings!$B$5,0),0) -> 0 | AH17: =IFERROR(IF(U17="","",IFERROR(VLOOKUP(U17,'Bucket Status'!$A$4:$B$75,2,FALSE()),0)-(SUMIF($U$5:$U16,U17,$AK$5:$AK16)+SUMIF($V$5:$V16,U17,$AL$5:$AL16)+SUMIF($Y$5:$Y16,U17,$AA$5:$AA16)+SUMIF($AC$5:$AC16,U17,$AE$5:$AE16))),"") -> 1.5 | AI17: =IFERROR(IF(V17="","",IFERROR(VLOOKUP(V17,'Bucket Status'!$A$4:$B$75,2,FALSE()),0)-(SUMIF($U$5:$U16,V17,$AK$5:$AK16)+SUMIF($V$5:$V16,V17,$AL$5:$AL16)+SUMIF($Y$5:$Y16,V17,$AA$5:$AA16)+SUMIF($AC$5:$AC16,V17,$AE$5:$AE16))),"") -> 3.99 | AJ17: =IFERROR(IF(AH17="","",AH17+IF(AI17="",0,AI17)),"") -> 5.49 | AK17: =IFERROR(IF(I17="","",IF(U17="",0,IF(V17="",(I17-AA17-AE17),MIN(AH17,(I17-AA17-AE17))))),"") -> 1.5 | AL17: =IFERROR(IF(I17="","",IF(V17="",0,MAX(0,(I17-AA17-AE17)-AK17))),"") -> 2.22
A18: B-2785 | B18: 46303 | D18: M3 | E18: B | H18: 4.66 | I18: =IFERROR(IF(H18="","",H18+AG18),"") -> 4.66 | J18: =IFERROR(IF(OR(I18="",AJ18=""),"",AJ18-(AK18+AL18)),"") -> 2.34 | K18: =IF(AND(AA18>0,AE18>0),TEXT(AA18,"0.000")&" kg "&Y18&" (funnel)"&" + "&TEXT(AE18,"0.000")&" kg "&AC18&" (funnel)",IF(AA18>0,TEXT(AA18,"0.000")&" kg "&Y18&" (funnel)",IF(AE18>0,TEXT(AE18,"0.000")&" kg "&AC18&" (funnel)",""))) | L18: =IF(OR(AK18="",AK18=0,U18=""),"",TEXT(AK18,"0.000")&" kg "&U18) -> 4.660 kg M3B- | M18: =IF(OR(AL18="",AL18=0,V18=""),"",TEXT(AL18,"0.000")&" kg "&V18) | N18: =IF(OR(I18="",U18=""),"",TEXT(MAX(0,(AH18-AK18-IF(Y18=U18,AA18,0)-IF(AC18=U18,AE18,0))),"0.000")&" kg "&U18) -> 0.570 kg M3B- | O18: =IF(OR(I18="",V18=""),"",TEXT(MAX(0,(AI18-AL18-IF(Y18=V18,AA18,0)-IF(AC18=V18,AE18,0))),"0.000")&" kg "&V18) -> 1.770 kg M2D- | Q18: =IF($A18="","",IF(D18="",Q17,D18)) -> M3 | R18: =IF($A18="","",IF(E18="",R17,E18)) -> B | S18: =IF($A18="","",IF(F18="",S17,F18)) -> M2 | T18: =IF($A18="","",IF(G18="",T17,G18)) -> D | U18: =IF(OR(Q18="",R18=""),"",Q18&R18&"-") -> M3B- | V18: =IF(OR(S18="",T18=""),"",S18&T18&"-") -> M2D- | W18: =IF(AND(U18<>"",U17<>"",U18<>U17),1,0) -> 1 | X18: =IF(AND(V18<>"",V17<>"",V18<>V17),1,0) -> 0 | Y18: =IF(W18=1,U17,IF(AB17>0,Y17,"")) -> M3A- | Z18: =IF(W18=1,MAX(0,MIN(Settings!$B$6,(IFERROR(VLOOKUP(U17,'Bucket Status'!$A$4:$B$75,2,FALSE()),0)-(SUMIF($U$5:$U17,U17,$AK$5:$AK17)+SUMIF($V$5:$V17,U17,$AL$5:$AL17)+SUMIF($Y$5:$Y17,U17,$AA$5:$AA17)+SUMIF($AC$5:$AC17,U17,$AE$5:$AE17))))),IF(AB17>0,AB17,0)) -> 0 | AA18: =IFERROR(IF(I18="",0,MAX(0,MIN(Z18,I18))),0) -> 0 | AB18: =IFERROR(Z18-AA18,0) -> 0 | AC18: =IF(X18=1,V17,IF(AF17>0,AC17,"")) | AD18: =IF(X18=1,MAX(0,MIN(Settings!$B$6-Z18,(IFERROR(VLOOKUP(V17,'Bucket Status'!$A$4:$B$75,2,FALSE()),0)-(SUMIF($U$5:$U17,V17,$AK$5:$AK17)+SUMIF($V$5:$V17,V17,$AL$5:$AL17)+SUMIF($Y$5:$Y17,V17,$AA$5:$AA17)+SUMIF($AC$5:$AC17,V17,$AE$5:$AE17))))),IF(AF17>0,AF17,0)) -> 0 | AE18: =IFERROR(IF(I18="",0,MAX(0,MIN(AD18,I18-AA18))),0) -> 0 | AF18: =IFERROR(AD18-AE18,0) -> 0 | AG18: =IFERROR(IF(C18="Y",Settings!$B$4+Settings!$B$5,0),0) -> 0 | AH18: =IFERROR(IF(U18="","",IFERROR(VLOOKUP(U18,'Bucket Status'!$A$4:$B$75,2,FALSE()),0)-(SUMIF($U$5:$U17,U18,$AK$5:$AK17)+SUMIF($V$5:$V17,U18,$AL$5:$AL17)+SUMIF($Y$5:$Y17,U18,$AA$5:$AA17)+SUMIF($AC$5:$AC17,U18,$AE$5:$AE17))),"") -> 5.23 | AI18: =IFERROR(IF(V18="","",IFERROR(VLOOKUP(V18,'Bucket Status'!$A$4:$B$75,2,FALSE()),0)-(SUMIF($U$5:$U17,V18,$AK$5:$AK17)+SUMIF($V$5:$V17,V18,$AL$5:$AL17)+SUMIF($Y$5:$Y17,V18,$AA$5:$AA17)+SUMIF($AC$5:$AC17,V18,$AE$5:$AE17))),"") -> 1.77 | AJ18: =IFERROR(IF(AH18="","",AH18+IF(AI18="",0,AI18)),"") -> 7 | AK18: =IFERROR(IF(I18="","",IF(U18="",0,IF(V18="",(I18-AA18-AE18),MIN(AH18,(I18-AA18-AE18))))),"") -> 4.66 | AL18: =IFERROR(IF(I18="","",IF(V18="",0,MAX(0,(I18-AA18-AE18)-AK18))),"") -> 0
A19: B-2789 | B19: 46304 | F19: M3 | G19: C | H19: 4.56 | I19: =IFERROR(IF(H19="","",H19+AG19),"") -> 4.56 | J19: =IFERROR(IF(OR(I19="",AJ19=""),"",AJ19-(AK19+AL19)),"") -> 2.86 | K19: =IF(AND(AA19>0,AE19>0),TEXT(AA19,"0.000")&" kg "&Y19&" (funnel)"&" + "&TEXT(AE19,"0.000")&" kg "&AC19&" (funnel)",IF(AA19>0,TEXT(AA19,"0.000")&" kg "&Y19&" (funnel)",IF(AE19>0,TEXT(AE19,"0.000")&" kg "&AC19&" (funnel)",""))) -> 1.770 kg M2D- (funnel) | L19: =IF(OR(AK19="",AK19=0,U19=""),"",TEXT(AK19,"0.000")&" kg "&U19) -> 0.570 kg M3B- | M19: =IF(OR(AL19="",AL19=0,V19=""),"",TEXT(AL19,"0.000")&" kg "&V19) -> 2.220 kg M3C- | N19: =IF(OR(I19="",U19=""),"",TEXT(MAX(0,(AH19-AK19-IF(Y19=U19,AA19,0)-IF(AC19=U19,AE19,0))),"0.000")&" kg "&U19) -> 0.000 kg M3B- | O19: =IF(OR(I19="",V19=""),"",TEXT(MAX(0,(AI19-AL19-IF(Y19=V19,AA19,0)-IF(AC19=V19,AE19,0))),"0.000")&" kg "&V19) -> 2.860 kg M3C- | Q19: =IF($A19="","",IF(D19="",Q18,D19)) -> M3 | R19: =IF($A19="","",IF(E19="",R18,E19)) -> B | S19: =IF($A19="","",IF(F19="",S18,F19)) -> M3 | T19: =IF($A19="","",IF(G19="",T18,G19)) -> C | U19: =IF(OR(Q19="",R19=""),"",Q19&R19&"-") -> M3B- | V19: =IF(OR(S19="",T19=""),"",S19&T19&"-") -> M3C- | W19: =IF(AND(U19<>"",U18<>"",U19<>U18),1,0) -> 0 | X19: =IF(AND(V19<>"",V18<>"",V19<>V18),1,0) -> 1 | Y19: =IF(W19=1,U18,IF(AB18>0,Y18,"")) | Z19: =IF(W19=1,MAX(0,MIN(Settings!$B$6,(IFERROR(VLOOKUP(U18,'Bucket Status'!$A$4:$B$75,2,FALSE()),0)-(SUMIF($U$5:$U18,U18,$AK$5:$AK18)+SUMIF($V$5:$V18,U18,$AL$5:$AL18)+SUMIF($Y$5:$Y18,U18,$AA$5:$AA18)+SUMIF($AC$5:$AC18,U18,$AE$5:$AE18))))),IF(AB18>0,AB18,0)) -> 0 | AA19: =IFERROR(IF(I19="",0,MAX(0,MIN(Z19,I19))),0) -> 0 | AB19: =IFERROR(Z19-AA19,0) -> 0 | AC19: =IF(X19=1,V18,IF(AF18>0,AC18,"")) -> M2D- | AD19: =IF(X19=1,MAX(0,MIN(Settings!$B$6-Z19,(IFERROR(VLOOKUP(V18,'Bucket Status'!$A$4:$B$75,2,FALSE()),0)-(SUMIF($U$5:$U18,V18,$AK$5:$AK18)+SUMIF($V$5:$V18,V18,$AL$5:$AL18)+SUMIF($Y$5:$Y18,V18,$AA$5:$AA18)+SUMIF($AC$5:$AC18,V18,$AE$5:$AE18))))),IF(AF18>0,AF18,0)) -> 1.77 | AE19: =IFERROR(IF(I19="",0,MAX(0,MIN(AD19,I19-AA19))),0) -> 1.77 | AF19: =IFERROR(AD19-AE19,0) -> 0 | AG19: =IFERROR(IF(C19="Y",Settings!$B$4+Settings!$B$5,0),0) -> 0 | AH19: =IFERROR(IF(U19="","",IFERROR(VLOOKUP(U19,'Bucket Status'!$A$4:$B$75,2,FALSE()),0)-(SUMIF($U$5:$U18,U19,$AK$5:$AK18)+SUMIF($V$5:$V18,U19,$AL$5:$AL18)+SUMIF($Y$5:$Y18,U19,$AA$5:$AA18)+SUMIF($AC$5:$AC18,U19,$AE$5:$AE18))),"") -> 0.57 | AI19: =IFERROR(IF(V19="","",IFERROR(VLOOKUP(V19,'Bucket Status'!$A$4:$B$75,2,FALSE()),0)-(SUMIF($U$5:$U18,V19,$AK$5:$AK18)+SUMIF($V$5:$V18,V19,$AL$5:$AL18)+SUMIF($Y$5:$Y18,V19,$AA$5:$AA18)+SUMIF($AC$5:$AC18,V19,$AE$5:$AE18))),"") -> 5.08 | AJ19: =IFERROR(IF(AH19="","",AH19+IF(AI19="",0,AI19)),"") -> 5.65 | AK19: =IFERROR(IF(I19="","",IF(U19="",0,IF(V19="",(I19-AA19-AE19),MIN(AH19,(I19-AA19-AE19))))),"") -> 0.57 | AL19: =IFERROR(IF(I19="","",IF(V19="",0,MAX(0,(I19-AA19-AE19)-AK19))),"") -> 2.22
A20: B-2792 | B20: 46307 | D20: M4 | E20: A | H20: 4.69 | I20: =IFERROR(IF(H20="","",H20+AG20),"") -> 4.69 | J20: =IFERROR(IF(OR(I20="",AJ20=""),"",AJ20-(AK20+AL20)),"") -> 3.27 | K20: =IF(AND(AA20>0,AE20>0),TEXT(AA20,"0.000")&" kg "&Y20&" (funnel)"&" + "&TEXT(AE20,"0.000")&" kg "&AC20&" (funnel)",IF(AA20>0,TEXT(AA20,"0.000")&" kg "&Y20&" (funnel)",IF(AE20>0,TEXT(AE20,"0.000")&" kg "&AC20&" (funnel)",""))) | L20: =IF(OR(AK20="",AK20=0,U20=""),"",TEXT(AK20,"0.000")&" kg "&U20) -> 4.690 kg M4A- | M20: =IF(OR(AL20="",AL20=0,V20=""),"",TEXT(AL20,"0.000")&" kg "&V20) | N20: =IF(OR(I20="",U20=""),"",TEXT(MAX(0,(AH20-AK20-IF(Y20=U20,AA20,0)-IF(AC20=U20,AE20,0))),"0.000")&" kg "&U20) -> 0.410 kg M4A- | O20: =IF(OR(I20="",V20=""),"",TEXT(MAX(0,(AI20-AL20-IF(Y20=V20,AA20,0)-IF(AC20=V20,AE20,0))),"0.000")&" kg "&V20) -> 2.860 kg M3C- | Q20: =IF($A20="","",IF(D20="",Q19,D20)) -> M4 | R20: =IF($A20="","",IF(E20="",R19,E20)) -> A | S20: =IF($A20="","",IF(F20="",S19,F20)) -> M3 | T20: =IF($A20="","",IF(G20="",T19,G20)) -> C | U20: =IF(OR(Q20="",R20=""),"",Q20&R20&"-") -> M4A- | V20: =IF(OR(S20="",T20=""),"",S20&T20&"-") -> M3C- | W20: =IF(AND(U20<>"",U19<>"",U20<>U19),1,0) -> 1 | X20: =IF(AND(V20<>"",V19<>"",V20<>V19),1,0) -> 0 | Y20: =IF(W20=1,U19,IF(AB19>0,Y19,"")) -> M3B- | Z20: =IF(W20=1,MAX(0,MIN(Settings!$B$6,(IFERROR(VLOOKUP(U19,'Bucket Status'!$A$4:$B$75,2,FALSE()),0)-(SUMIF($U$5:$U19,U19,$AK$5:$AK19)+SUMIF($V$5:$V19,U19,$AL$5:$AL19)+SUMIF($Y$5:$Y19,U19,$AA$5:$AA19)+SUMIF($AC$5:$AC19,U19,$AE$5:$AE19))))),IF(AB19>0,AB19,0)) -> 0 | AA20: =IFERROR(IF(I20="",0,MAX(0,MIN(Z20,I20))),0) -> 0 | AB20: =IFERROR(Z20-AA20,0) -> 0 | AC20: =IF(X20=1,V19,IF(AF19>0,AC19,"")) | AD20: =IF(X20=1,MAX(0,MIN(Settings!$B$6-Z20,(IFERROR(VLOOKUP(V19,'Bucket Status'!$A$4:$B$75,2,FALSE()),0)-(SUMIF($U$5:$U19,V19,$AK$5:$AK19)+SUMIF($V$5:$V19,V19,$AL$5:$AL19)+SUMIF($Y$5:$Y19,V19,$AA$5:$AA19)+SUMIF($AC$5:$AC19,V19,$AE$5:$AE19))))),IF(AF19>0,AF19,0)) -> 0 | AE20: =IFERROR(IF(I20="",0,MAX(0,MIN(AD20,I20-AA20))),0) -> 0 | AF20: =IFERROR(AD20-AE20,0) -> 0 | AG20: =IFERROR(IF(C20="Y",Settings!$B$4+Settings!$B$5,0),0) -> 0 | AH20: =IFERROR(IF(U20="","",IFERROR(VLOOKUP(U20,'Bucket Status'!$A$4:$B$75,2,FALSE()),0)-(SUMIF($U$5:$U19,U20,$AK$5:$AK19)+SUMIF($V$5:$V19,U20,$AL$5:$AL19)+SUMIF($Y$5:$Y19,U20,$AA$5:$AA19)+SUMIF($AC$5:$AC19,U20,$AE$5:$AE19))),"") -> 5.1 | AI20: =IFERROR(IF(V20="","",IFERROR(VLOOKUP(V20,'Bucket Status'!$A$4:$B$75,2,FALSE()),0)-(SUMIF($U$5:$U19,V20,$AK$5:$AK19)+SUMIF($V$5:$V19,V20,$AL$5:$AL19)+SUMIF($Y$5:$Y19,V20,$AA$5:$AA19)+SUMIF($AC$5:$AC19,V20,$AE$5:$AE19))),"") -> 2.86 | AJ20: =IFERROR(IF(AH20="","",AH20+IF(AI20="",0,AI20)),"") -> 7.96 | AK20: =IFERROR(IF(I20="","",IF(U20="",0,IF(V20="",(I20-AA20-AE20),MIN(AH20,(I20-AA20-AE20))))),"") -> 4.69 | AL20: =IFERROR(IF(I20="","",IF(V20="",0,MAX(0,(I20-AA20-AE20)-AK20))),"") -> 0
A21: B-2792(2nd) | B21: 46308 | F21: M4 | G21: B | H21: 4.69 | I21: =IFERROR(IF(H21="","",H21+AG21),"") -> 4.69 | J21: =IFERROR(IF(OR(I21="",AJ21=""),"",AJ21-(AK21+AL21)),"") -> 3.68 | K21: =IF(AND(AA21>0,AE21>0),TEXT(AA21,"0.000")&" kg "&Y21&" (funnel)"&" + "&TEXT(AE21,"0.000")&" kg "&AC21&" (funnel)",IF(AA21>0,TEXT(AA21,"0.000")&" kg "&Y21&" (funnel)",IF(AE21>0,TEXT(AE21,"0.000")&" kg "&AC21&" (funnel)",""))) -> 2.860 kg M3C- (funnel) | L21: =IF(OR(AK21="",AK21=0,U21=""),"",TEXT(AK21,"0.000")&" kg "&U21) -> 0.410 kg M4A- | M21: =IF(OR(AL21="",AL21=0,V21=""),"",TEXT(AL21,"0.000")&" kg "&V21) -> 1.420 kg M4B- | N21: =IF(OR(I21="",U21=""),"",TEXT(MAX(0,(AH21-AK21-IF(Y21=U21,AA21,0)-IF(AC21=U21,AE21,0))),"0.000")&" kg "&U21) -> 0.000 kg M4A- | O21: =IF(OR(I21="",V21=""),"",TEXT(MAX(0,(AI21-AL21-IF(Y21=V21,AA21,0)-IF(AC21=V21,AE21,0))),"0.000")&" kg "&V21) -> 3.680 kg M4B- | Q21: =IF($A21="","",IF(D21="",Q20,D21)) -> M4 | R21: =IF($A21="","",IF(E21="",R20,E21)) -> A | S21: =IF($A21="","",IF(F21="",S20,F21)) -> M4 | T21: =IF($A21="","",IF(G21="",T20,G21)) -> B | U21: =IF(OR(Q21="",R21=""),"",Q21&R21&"-") -> M4A- | V21: =IF(OR(S21="",T21=""),"",S21&T21&"-") -> M4B- | W21: =IF(AND(U21<>"",U20<>"",U21<>U20),1,0) -> 0 | X21: =IF(AND(V21<>"",V20<>"",V21<>V20),1,0) -> 1 | Y21: =IF(W21=1,U20,IF(AB20>0,Y20,"")) | Z21: =IF(W21=1,MAX(0,MIN(Settings!$B$6,(IFERROR(VLOOKUP(U20,'Bucket Status'!$A$4:$B$75,2,FALSE()),0)-(SUMIF($U$5:$U20,U20,$AK$5:$AK20)+SUMIF($V$5:$V20,U20,$AL$5:$AL20)+SUMIF($Y$5:$Y20,U20,$AA$5:$AA20)+SUMIF($AC$5:$AC20,U20,$AE$5:$AE20))))),IF(AB20>0,AB20,0)) -> 0 | AA21: =IFERROR(IF(I21="",0,MAX(0,MIN(Z21,I21))),0) -> 0 | AB21: =IFERROR(Z21-AA21,0) -> 0 | AC21: =IF(X21=1,V20,IF(AF20>0,AC20,"")) -> M3C- | AD21: =IF(X21=1,MAX(0,MIN(Settings!$B$6-Z21,(IFERROR(VLOOKUP(V20,'Bucket Status'!$A$4:$B$75,2,FALSE()),0)-(SUMIF($U$5:$U20,V20,$AK$5:$AK20)+SUMIF($V$5:$V20,V20,$AL$5:$AL20)+SUMIF($Y$5:$Y20,V20,$AA$5:$AA20)+SUMIF($AC$5:$AC20,V20,$AE$5:$AE20))))),IF(AF20>0,AF20,0)) -> 2.86 | AE21: =IFERROR(IF(I21="",0,MAX(0,MIN(AD21,I21-AA21))),0) -> 2.86 | AF21: =IFERROR(AD21-AE21,0) -> 0 | AG21: =IFERROR(IF(C21="Y",Settings!$B$4+Settings!$B$5,0),0) -> 0 | AH21: =IFERROR(IF(U21="","",IFERROR(VLOOKUP(U21,'Bucket Status'!$A$4:$B$75,2,FALSE()),0)-(SUMIF($U$5:$U20,U21,$AK$5:$AK20)+SUMIF($V$5:$V20,U21,$AL$5:$AL20)+SUMIF($Y$5:$Y20,U21,$AA$5:$AA20)+SUMIF($AC$5:$AC20,U21,$AE$5:$AE20))),"") -> 0.41 | AI21: =IFERROR(IF(V21="","",IFERROR(VLOOKUP(V21,'Bucket Status'!$A$4:$B$75,2,FALSE()),0)-(SUMIF($U$5:$U20,V21,$AK$5:$AK20)+SUMIF($V$5:$V20,V21,$AL$5:$AL20)+SUMIF($Y$5:$Y20,V21,$AA$5:$AA20)+SUMIF($AC$5:$AC20,V21,$AE$5:$AE20))),"") -> 5.1 | AJ21: =IFERROR(IF(AH21="","",AH21+IF(AI21="",0,AI21)),"") -> 5.51 | AK21: =IFERROR(IF(I21="","",IF(U21="",0,IF(V21="",(I21-AA21-AE21),MIN(AH21,(I21-AA21-AE21))))),"") -> 0.41 | AL21: =IFERROR(IF(I21="","",IF(V21="",0,MAX(0,(I21-AA21-AE21)-AK21))),"") -> 1.42
A22: B-2792(3rd) | B22: 46309 | D22: M4 | E22: C | I22: =IFERROR(IF(H22="","",H22+AG22),"") | J22: =IFERROR(IF(OR(I22="",AJ22=""),"",AJ22-(AK22+AL22)),"") | K22: =IF(AND(AA22>0,AE22>0),TEXT(AA22,"0.000")&" kg "&Y22&" (funnel)"&" + "&TEXT(AE22,"0.000")&" kg "&AC22&" (funnel)",IF(AA22>0,TEXT(AA22,"0.000")&" kg "&Y22&" (funnel)",IF(AE22>0,TEXT(AE22,"0.000")&" kg "&AC22&" (funnel)",""))) | L22: =IF(OR(AK22="",AK22=0,U22=""),"",TEXT(AK22,"0.000")&" kg "&U22) | M22: =IF(OR(AL22="",AL22=0,V22=""),"",TEXT(AL22,"0.000")&" kg "&V22) | N22: =IF(OR(I22="",U22=""),"",TEXT(MAX(0,(AH22-AK22-IF(Y22=U22,AA22,0)-IF(AC22=U22,AE22,0))),"0.000")&" kg "&U22) | O22: =IF(OR(I22="",V22=""),"",TEXT(MAX(0,(AI22-AL22-IF(Y22=V22,AA22,0)-IF(AC22=V22,AE22,0))),"0.000")&" kg "&V22) | Q22: =IF($A22="","",IF(D22="",Q21,D22)) -> M4 | R22: =IF($A22="","",IF(E22="",R21,E22)) -> C | S22: =IF($A22="","",IF(F22="",S21,F22)) -> M4 | T22: =IF($A22="","",IF(G22="",T21,G22)) -> B | U22: =IF(OR(Q22="",R22=""),"",Q22&R22&"-") -> M4C- | V22: =IF(OR(S22="",T22=""),"",S22&T22&"-") -> M4B- | W22: =IF(AND(U22<>"",U21<>"",U22<>U21),1,0) -> 1 | X22: =IF(AND(V22<>"",V21<>"",V22<>V21),1,0) -> 0 | Y22: =IF(W22=1,U21,IF(AB21>0,Y21,"")) -> M4A- | Z22: =IF(W22=1,MAX(0,MIN(Settings!$B$6,(IFERROR(VLOOKUP(U21,'Bucket Status'!$A$4:$B$75,2,FALSE()),0)-(SUMIF($U$5:$U21,U21,$AK$5:$AK21)+SUMIF($V$5:$V21,U21,$AL$5:$AL21)+SUMIF($Y$5:$Y21,U21,$AA$5:$AA21)+SUMIF($AC$5:$AC21,U21,$AE$5:$AE21))))),IF(AB21>0,AB21,0)) -> 0 | AA22: =IFERROR(IF(I22="",0,MAX(0,MIN(Z22,I22))),0) -> 0 | AB22: =IFERROR(Z22-AA22,0) -> 0 | AC22: =IF(X22=1,V21,IF(AF21>0,AC21,"")) | AD22: =IF(X22=1,MAX(0,MIN(Settings!$B$6-Z22,(IFERROR(VLOOKUP(V21,'Bucket Status'!$A$4:$B$75,2,FALSE()),0)-(SUMIF($U$5:$U21,V21,$AK$5:$AK21)+SUMIF($V$5:$V21,V21,$AL$5:$AL21)+SUMIF($Y$5:$Y21,V21,$AA$5:$AA21)+SUMIF($AC$5:$AC21,V21,$AE$5:$AE21))))),IF(AF21>0,AF21,0)) -> 0 | AE22: =IFERROR(IF(I22="",0,MAX(0,MIN(AD22,I22-AA22))),0) -> 0 | AF22: =IFERROR(AD22-AE22,0) -> 0 | AG22: =IFERROR(IF(C22="Y",Settings!$B$4+Settings!$B$5,0),0) -> 0 | AH22: =IFERROR(IF(U22="","",IFERROR(VLOOKUP(U22,'Bucket Status'!$A$4:$B$75,2,FALSE()),0)-(SUMIF($U$5:$U21,U22,$AK$5:$AK21)+SUMIF($V$5:$V21,U22,$AL$5:$AL21)+SUMIF($Y$5:$Y21,U22,$AA$5:$AA21)+SUMIF($AC$5:$AC21,U22,$AE$5:$AE21))),"") -> 4.98 | AI22: =IFERROR(IF(V22="","",IFERROR(VLOOKUP(V22,'Bucket Status'!$A$4:$B$75,2,FALSE()),0)-(SUMIF($U$5:$U21,V22,$AK$5:$AK21)+SUMIF($V$5:$V21,V22,$AL$5:$AL21)+SUMIF($Y$5:$Y21,V22,$AA$5:$AA21)+SUMIF($AC$5:$AC21,V22,$AE$5:$AE21))),"") -> 3.68 | AJ22: =IFERROR(IF(AH22="","",AH22+IF(AI22="",0,AI22)),"") -> 8.66 | AK22: =IFERROR(IF(I22="","",IF(U22="",0,IF(V22="",(I22-AA22-AE22),MIN(AH22,(I22-AA22-AE22))))),"") | AL22: =IFERROR(IF(I22="","",IF(V22="",0,MAX(0,(I22-AA22-AE22)-AK22))),"")
I23: =IFERROR(IF(H23="","",H23+AG23),"") | J23: =IFERROR(IF(OR(I23="",AJ23=""),"",AJ23-(AK23+AL23)),"") | K23: =IF(AND(AA23>0,AE23>0),TEXT(AA23,"0.000")&" kg "&Y23&" (funnel)"&" + "&TEXT(AE23,"0.000")&" kg "&AC23&" (funnel)",IF(AA23>0,TEXT(AA23,"0.000")&" kg "&Y23&" (funnel)",IF(AE23>0,TEXT(AE23,"0.000")&" kg "&AC23&" (funnel)",""))) | L23: =IF(OR(AK23="",AK23=0,U23=""),"",TEXT(AK23,"0.000")&" kg "&U23) | M23: =IF(OR(AL23="",AL23=0,V23=""),"",TEXT(AL23,"0.000")&" kg "&V23) | N23: =IF(OR(I23="",U23=""),"",TEXT(MAX(0,(AH23-AK23-IF(Y23=U23,AA23,0)-IF(AC23=U23,AE23,0))),"0.000")&" kg "&U23) | O23: =IF(OR(I23="",V23=""),"",TEXT(MAX(0,(AI23-AL23-IF(Y23=V23,AA23,0)-IF(AC23=V23,AE23,0))),"0.000")&" kg "&V23) | Q23: =IF($A23="","",IF(D23="",Q22,D23)) | R23: =IF($A23="","",IF(E23="",R22,E23)) | S23: =IF($A23="","",IF(F23="",S22,F23)) | T23: =IF($A23="","",IF(G23="",T22,G23)) | U23: =IF(OR(Q23="",R23=""),"",Q23&R23&"-") | V23: =IF(OR(S23="",T23=""),"",S23&T23&"-") | W23: =IF(AND(U23<>"",U22<>"",U23<>U22),1,0) -> 0 | X23: =IF(AND(V23<>"",V22<>"",V23<>V22),1,0) -> 0 | Y23: =IF(W23=1,U22,IF(AB22>0,Y22,"")) | Z23: =IF(W23=1,MAX(0,MIN(Settings!$B$6,(IFERROR(VLOOKUP(U22,'Bucket Status'!$A$4:$B$75,2,FALSE()),0)-(SUMIF($U$5:$U22,U22,$AK$5:$AK22)+SUMIF($V$5:$V22,U22,$AL$5:$AL22)+SUMIF($Y$5:$Y22,U22,$AA$5:$AA22)+SUMIF($AC$5:$AC22,U22,$AE$5:$AE22))))),IF(AB22>0,AB22,0)) -> 0 | AA23: =IFERROR(IF(I23="",0,MAX(0,MIN(Z23,I23))),0) -> 0 | AB23: =IFERROR(Z23-AA23,0) -> 0 | AC23: =IF(X23=1,V22,IF(AF22>0,AC22,"")) | AD23: =IF(X23=1,MAX(0,MIN(Settings!$B$6-Z23,(IFERROR(VLOOKUP(V22,'Bucket Status'!$A$4:$B$75,2,FALSE()),0)-(SUMIF($U$5:$U22,V22,$AK$5:$AK22)+SUMIF($V$5:$V22,V22,$AL$5:$AL22)+SUMIF($Y$5:$Y22,V22,$AA$5:$AA22)+SUMIF($AC$5:$AC22,V22,$AE$5:$AE22))))),IF(AF22>0,AF22,0)) -> 0 | AE23: =IFERROR(IF(I23="",0,MAX(0,MIN(AD23,I23-AA23))),0) -> 0 | AF23: =IFERROR(AD23-AE23,0) -> 0 | AG23: =IFERROR(IF(C23="Y",Settings!$B$4+Settings!$B$5,0),0) -> 0 | AH23: =IFERROR(IF(U23="","",IFERROR(VLOOKUP(U23,'Bucket Status'!$A$4:$B$75,2,FALSE()),0)-(SUMIF($U$5:$U22,U23,$AK$5:$AK22)+SUMIF($V$5:$V22,U23,$AL$5:$AL22)+SUMIF($Y$5:$Y22,U23,$AA$5:$AA22)+SUMIF($AC$5:$AC22,U23,$AE$5:$AE22))),"") | AI23: =IFERROR(IF(V23="","",IFERROR(VLOOKUP(V23,'Bucket Status'!$A$4:$B$75,2,FALSE()),0)-(SUMIF($U$5:$U22,V23,$AK$5:$AK22)+SUMIF($V$5:$V22,V23,$AL$5:$AL22)+SUMIF($Y$5:$Y22,V23,$AA$5:$AA22)+SUMIF($AC$5:$AC22,V23,$AE$5:$AE22))),"") | AJ23: =IFERROR(IF(AH23="","",AH23+IF(AI23="",0,AI23)),"") | AK23: =IFERROR(IF(I23="","",IF(U23="",0,IF(V23="",(I23-AA23-AE23),MIN(AH23,(I23-AA23-AE23))))),"") | AL23: =IFERROR(IF(I23="","",IF(V23="",0,MAX(0,(I23-AA23-AE23)-AK23))),"")
I24: =IFERROR(IF(H24="","",H24+AG24),"") | J24: =IFERROR(IF(OR(I24="",AJ24=""),"",AJ24-(AK24+AL24)),"") | K24: =IF(AND(AA24>0,AE24>0),TEXT(AA24,"0.000")&" kg "&Y24&" (funnel)"&" + "&TEXT(AE24,"0.000")&" kg "&AC24&" (funnel)",IF(AA24>0,TEXT(AA24,"0.000")&" kg "&Y24&" (funnel)",IF(AE24>0,TEXT(AE24,"0.000")&" kg "&AC24&" (funnel)",""))) | L24: =IF(OR(AK24="",AK24=0,U24=""),"",TEXT(AK24,"0.000")&" kg "&U24) | M24: =IF(OR(AL24="",AL24=0,V24=""),"",TEXT(AL24,"0.000")&" kg "&V24) | N24: =IF(OR(I24="",U24=""),"",TEXT(MAX(0,(AH24-AK24-IF(Y24=U24,AA24,0)-IF(AC24=U24,AE24,0))),"0.000")&" kg "&U24) | O24: =IF(OR(I24="",V24=""),"",TEXT(MAX(0,(AI24-AL24-IF(Y24=V24,AA24,0)-IF(AC24=V24,AE24,0))),"0.000")&" kg "&V24) | Q24: =IF($A24="","",IF(D24="",Q23,D24)) | R24: =IF($A24="","",IF(E24="",R23,E24)) | S24: =IF($A24="","",IF(F24="",S23,F24)) | T24: =IF($A24="","",IF(G24="",T23,G24)) | U24: =IF(OR(Q24="",R24=""),"",Q24&R24&"-") | V24: =IF(OR(S24="",T24=""),"",S24&T24&"-") | W24: =IF(AND(U24<>"",U23<>"",U24<>U23),1,0) -> 0 | X24: =IF(AND(V24<>"",V23<>"",V24<>V23),1,0) -> 0 | Y24: =IF(W24=1,U23,IF(AB23>0,Y23,"")) | Z24: =IF(W24=1,MAX(0,MIN(Settings!$B$6,(IFERROR(VLOOKUP(U23,'Bucket Status'!$A$4:$B$75,2,FALSE()),0)-(SUMIF($U$5:$U23,U23,$AK$5:$AK23)+SUMIF($V$5:$V23,U23,$AL$5:$AL23)+SUMIF($Y$5:$Y23,U23,$AA$5:$AA23)+SUMIF($AC$5:$AC23,U23,$AE$5:$AE23))))),IF(AB23>0,AB23,0)) -> 0 | AA24: =IFERROR(IF(I24="",0,MAX(0,MIN(Z24,I24))),0) -> 0 | AB24: =IFERROR(Z24-AA24,0) -> 0 | AC24: =IF(X24=1,V23,IF(AF23>0,AC23,"")) | AD24: =IF(X24=1,MAX(0,MIN(Settings!$B$6-Z24,(IFERROR(VLOOKUP(V23,'Bucket Status'!$A$4:$B$75,2,FALSE()),0)-(SUMIF($U$5:$U23,V23,$AK$5:$AK23)+SUMIF($V$5:$V23,V23,$AL$5:$AL23)+SUMIF($Y$5:$Y23,V23,$AA$5:$AA23)+SUMIF($AC$5:$AC23,V23,$AE$5:$AE23))))),IF(AF23>0,AF23,0)) -> 0 | AE24: =IFERROR(IF(I24="",0,MAX(0,MIN(AD24,I24-AA24))),0) -> 0 | AF24: =IFERROR(AD24-AE24,0) -> 0 | AG24: =IFERROR(IF(C24="Y",Settings!$B$4+Settings!$B$5,0),0) -> 0 | AH24: =IFERROR(IF(U24="","",IFERROR(VLOOKUP(U24,'Bucket Status'!$A$4:$B$75,2,FALSE()),0)-(SUMIF($U$5:$U23,U24,$AK$5:$AK23)+SUMIF($V$5:$V23,U24,$AL$5:$AL23)+SUMIF($Y$5:$Y23,U24,$AA$5:$AA23)+SUMIF($AC$5:$AC23,U24,$AE$5:$AE23))),"") | AI24: =IFERROR(IF(V24="","",IFERROR(VLOOKUP(V24,'Bucket Status'!$A$4:$B$75,2,FALSE()),0)-(SUMIF($U$5:$U23,V24,$AK$5:$AK23)+SUMIF($V$5:$V23,V24,$AL$5:$AL23)+SUMIF($Y$5:$Y23,V24,$AA$5:$AA23)+SUMIF($AC$5:$AC23,V24,$AE$5:$AE23))),"") | AJ24: =IFERROR(IF(AH24="","",AH24+IF(AI24="",0,AI24)),"") | AK24: =IFERROR(IF(I24="","",IF(U24="",0,IF(V24="",(I24-AA24-AE24),MIN(AH24,(I24-AA24-AE24))))),"") | AL24: =IFERROR(IF(I24="","",IF(V24="",0,MAX(0,(I24-AA24-AE24)-AK24))),"")
I25: =IFERROR(IF(H25="","",H25+AG25),"") | J25: =IFERROR(IF(OR(I25="",AJ25=""),"",AJ25-(AK25+AL25)),"") | K25: =IF(AND(AA25>0,AE25>0),TEXT(AA25,"0.000")&" kg "&Y25&" (funnel)"&" + "&TEXT(AE25,"0.000")&" kg "&AC25&" (funnel)",IF(AA25>0,TEXT(AA25,"0.000")&" kg "&Y25&" (funnel)",IF(AE25>0,TEXT(AE25,"0.000")&" kg "&AC25&" (funnel)",""))) | L25: =IF(OR(AK25="",AK25=0,U25=""),"",TEXT(AK25,"0.000")&" kg "&U25) | M25: =IF(OR(AL25="",AL25=0,V25=""),"",TEXT(AL25,"0.000")&" kg "&V25) | N25: =IF(OR(I25="",U25=""),"",TEXT(MAX(0,(AH25-AK25-IF(Y25=U25,AA25,0)-IF(AC25=U25,AE25,0))),"0.000")&" kg "&U25) | O25: =IF(OR(I25="",V25=""),"",TEXT(MAX(0,(AI25-AL25-IF(Y25=V25,AA25,0)-IF(AC25=V25,AE25,0))),"0.000")&" kg "&V25) | Q25: =IF($A25="","",IF(D25="",Q24,D25)) | R25: =IF($A25="","",IF(E25="",R24,E25)) | S25: =IF($A25="","",IF(F25="",S24,F25)) | T25: =IF($A25="","",IF(G25="",T24,G25)) | U25: =IF(OR(Q25="",R25=""),"",Q25&R25&"-") | V25: =IF(OR(S25="",T25=""),"",S25&T25&"-") | W25: =IF(AND(U25<>"",U24<>"",U25<>U24),1,0) -> 0 | X25: =IF(AND(V25<>"",V24<>"",V25<>V24),1,0) -> 0 | Y25: =IF(W25=1,U24,IF(AB24>0,Y24,"")) | Z25: =IF(W25=1,MAX(0,MIN(Settings!$B$6,(IFERROR(VLOOKUP(U24,'Bucket Status'!$A$4:$B$75,2,FALSE()),0)-(SUMIF($U$5:$U24,U24,$AK$5:$AK24)+SUMIF($V$5:$V24,U24,$AL$5:$AL24)+SUMIF($Y$5:$Y24,U24,$AA$5:$AA24)+SUMIF($AC$5:$AC24,U24,$AE$5:$AE24))))),IF(AB24>0,AB24,0)) -> 0 | AA25: =IFERROR(IF(I25="",0,MAX(0,MIN(Z25,I25))),0) -> 0 | AB25: =IFERROR(Z25-AA25,0) -> 0 | AC25: =IF(X25=1,V24,IF(AF24>0,AC24,"")) | AD25: =IF(X25=1,MAX(0,MIN(Settings!$B$6-Z25,(IFERROR(VLOOKUP(V24,'Bucket Status'!$A$4:$B$75,2,FALSE()),0)-(SUMIF($U$5:$U24,V24,$AK$5:$AK24)+SUMIF($V$5:$V24,V24,$AL$5:$AL24)+SUMIF($Y$5:$Y24,V24,$AA$5:$AA24)+SUMIF($AC$5:$AC24,V24,$AE$5:$AE24))))),IF(AF24>0,AF24,0)) -> 0 | AE25: =IFERROR(IF(I25="",0,MAX(0,MIN(AD25,I25-AA25))),0) -> 0 | AF25: =IFERROR(AD25-AE25,0) -> 0 | AG25: =IFERROR(IF(C25="Y",Settings!$B$4+Settings!$B$5,0),0) -> 0 | AH25: =IFERROR(IF(U25="","",IFERROR(VLOOKUP(U25,'Bucket Status'!$A$4:$B$75,2,FALSE()),0)-(SUMIF($U$5:$U24,U25,$AK$5:$AK24)+SUMIF($V$5:$V24,U25,$AL$5:$AL24)+SUMIF($Y$5:$Y24,U25,$AA$5:$AA24)+SUMIF($AC$5:$AC24,U25,$AE$5:$AE24))),"") | AI25: =IFERROR(IF(V25="","",IFERROR(VLOOKUP(V25,'Bucket Status'!$A$4:$B$75,2,FALSE()),0)-(SUMIF($U$5:$U24,V25,$AK$5:$AK24)+SUMIF($V$5:$V24,V25,$AL$5:$AL24)+SUMIF($Y$5:$Y24,V25,$AA$5:$AA24)+SUMIF($AC$5:$AC24,V25,$AE$5:$AE24))),"") | AJ25: =IFERROR(IF(AH25="","",AH25+IF(AI25="",0,AI25)),"") | AK25: =IFERROR(IF(I25="","",IF(U25="",0,IF(V25="",(I25-AA25-AE25),MIN(AH25,(I25-AA25-AE25))))),"") | AL25: =IFERROR(IF(I25="","",IF(V25="",0,MAX(0,(I25-AA25-AE25)-AK25))),"")
